Workbook

Sheet LEEME
A1: Costo total del evento de Argentina · CMC 2026
A2: La Rural, Pabellón Azul — montaje 2 de octubre, evento 3 y 4 de octubre de 2026.
A4: Qué es esto | B4: Unifica los presupuestos que llegaron por mail (jun-ago 2026) con la hoja "Argentina (3 oct-4 oct)" del master de inversión, para poder decir cuánto sale el evento de verdad y cuánto por persona.
A5: Fecha de corte | B5: Todo calculado al 02/09/2026.
A6: Tipo de cambio | B6: Celda TABLERO!C4, editable. $1.510, que es el dólar con el que viene trabajando Agustina. Se verificó contra dos de sus cifras: el montaje de $900.000 le da US$596 y el entelado de $24.500.000 le da US$16.225. Todas las conversiones de pesos a dólares salen de esa única celda.
A8: Cómo leer los estados | B8: Contratado = hay contrato o anticipo pagado. Cotizado = hay presupuesto formal por mail. Alternativa = segunda opción para el mismo ítem, NO suma al total. Otro país = es un gasto de otro evento de la gira, entra en cero. Reemplazado = estimado viejo que ya está cubierto por facturas reales, entra en cero. Sin cotizar = sólo hay un estimado del sheet, o ni eso.
A9: Columna "% Argentina" | B9: Es la parte de cada compra que se le imputa a este evento. Vale 100% en casi todo. Los pañuelos son una compra compartida con Uruguay y van al 65% (5.500 de 8.500 unidades); la gráfica de Uruguay va al 0%.
A10: Regla del total | B10: El total suma los ítems Contratado + Cotizado + Sin cotizar. Los marcados "Alternativa" quedan fuera para no duplicar (las sillas de La Rural vs las de FDL, y las LED de VMG contra la técnica integral de Prina).
A11: IVA | B11: Las cotizaciones argentinas casi todas vienen sin IVA. La columna IVA aplica la alícuota de cada una (21% general, 10,5% el servicio médico) para llegar al costo real.
A13: Advertencia 1 — vencimientos | B13: La cotización de Prina (técnica, el ítem más caro en pesos) tenía validez de 10 días y venció en junio. VMG se reserva recotizar si el dólar salta más de 15%. La Rural ajusta el saldo por IPC. Los pesos de este libro son de la fecha de cada cotización, no de hoy.
A14: Advertencia 2 — huecos | B14: Vuelos y alojamiento del equipo entran en cero: no hay cotización ni estimado. Tampoco están cotizados los ecobaños, la marquetería, el replanteo de sillas ni los cheques, escarapelas, diplomas, placas y manillas. El costo por persona es, por lo tanto, un piso.
A16: Merch | B16: Todo el merch sale de la carpeta de Drive "Presupuestos merch": nueve facturas reales (2601009 a 2601019) que reemplazan el renglón único de US$8.689 que traía el master. Los proveedores son argentinos (Remerasyestampados, Textil Ryu, Leotex, Derqui), no colombianos como decía la hoja PAGOS. Ver la hoja MERCH.
A17: Merch — qué se pagó | B17: Las gorras están pagadas al 100%. Pañuelos, lanyards y gráfica de Argentina tienen el 50% abonado. Las remeras y el bordado de las gorras no tienen nada pagado: se debe el 100%.
A18: Merch — dos ajustes | B18: Se sacaron dos duplicaciones: las cintas de Blocko eran el mismo ítem que los lanyards de Leotex ya contratados, y la gráfica de Uruguay (US$1.233) estaba cargada en el master con país = Argentina.
... A22: Fuente de planilla | B22: INVERSIÓN GIRA CUMBRE 2026.xlsx — hojas "Argentina (3 oct-4 oct)" y "PAGOS".

Sheet COSTOS UNIFICADOS
A1: Todos los costos de Argentina, bloque por bloque
A2: Una fila por concepto. "Monto a usar" toma la cotización real cuando existe y el estimado del sheet cuando no.
A4: Rubro | B4: Proveedor | C4: Detalle | D4: Estado | E4: Moneda | F4: Monto sin IVA | G4: IVA | H4: Total moneda origen | I4: % Argentina | J4: Total USD | K4: Estimado del sheet (USD) | L4: Diferencia | M4: Fuente
A5: SEDE
A6: Alquiler Pabellón Azul | B6: La Rural (contrato CC-00957) | C6: Locación 2 días de evento + 1 día de montaje | D6: Contratado | E6: USD | F6: 75000 | H6: =IF(F6="","",F6*(1+N(G6))) | I6: 1 | J6: =IF(OR(D6="Bonificado",D6="Reemplazado"),0,N(I6)*IF(H6="",N(K6),IF(E6="USD",H6,H6/TABLERO!$C$4))) | K6: 70000 | L6: =IF(D6="Alternativa","",J6-N(K6)) | M6: Contrato CC-00957 · hoja PAGOS del master (US$43.446 abonados el 27/04)
A7: Subtotal Sede | J7: =SUMIF($D$6:$D$6,"<>Alternativa",$J$6:$J$6) | K7: =SUM($K$6:$K$6) | L7: =J7-K7
A8: INFRAESTRUCTURA
A9: Armado de stands | B9: La Rural — Jefatura de Infraestructura | C9: Armado del stand de staff (100 m²), el de producción (menos de 50 m²) y el mobiliario del camarín de speakers. Falta pedirles los espejos. Las sillas del público van en su propia línea. | D9: Cerrado | E9: USD | F9: 9270 | H9: =IF(F9="","",F9*(1+N(G9))) | I9: 1 | J9: =IF(OR(D9="Bonificado",D9="Reemplazado"),0,N(I9)*IF(H9="",N(K9),IF(E9="USD",H9,H9/TABLERO!$C$4))) | L9: =IF(D9="Alternativa","",J9-N(K9)) | M9: Definición de Agustina sobre el presupuesto de $66.494.708 del 17/08 · ver hoja AHORROS
A10: Subtotal Infraestructura | J10: =SUMIF($D$9:$D$9,"<>Alternativa",$J$9:$J$9) | K10: =SUM($K$9:$K$9) | L10: =J10-K10
A11: MOBILIARIO
A12: Sillas del público (5.500) | B12: FDL Eventos | C12: Presupuesto 026-2697, alquiler por 4 días: 1.000 sillas hotel caño gris tapizado negro ($7.000.000) + 4.500 sillas plásticas Munro reforzadas ($17.100.000) + flete ($1.700.000). NO incluye armado. | D12: Cotizado | E12: ARS | F12: 25800000 | G12: 0.21 | H12: =IF(F12="","",F12*(1+N(G12))) | I12: 1 | J12: =IF(OR(D12="Bonificado",D12="Reemplazado"),0,N(I12)*IF(H12="",N(K12),IF(E12="USD",H12,H12/TABLERO!$C$4))) | K12: 16500 | L12: =IF(D12="Alternativa","",J12-N(K12)) | M12: Presupuesto FDL Eventos N.º 026-2697 del 07/08/2026 · pendiente de resolver facturación al exterior
A13: Montaje, acomodación y desmontaje de sillas | B13: En negociación | C13: Montaje previo, acomodación el sábado a la noche después de la dinámica y desmontaje el domingo. | D13: En negociación | E13: ARS | F13: 900000 | H13: =IF(F13="","",F13*(1+N(G13))) | I13: 1 | J13: =IF(OR(D13="Bonificado",D13="Reemplazado"),0,N(I13)*IF(H13="",N(K13),IF(E13="USD",H13,H13/TABLERO!$C$4))) | L13: =IF(D13="Alternativa","",J13-N(K13)) | M13: Negociación de Agustina · cerrar el número antes de firmar las sillas
A14: Replanteo de sillas (ingeniero) | B14: Sin cotizar | C14: Replanteo del layout de sillas del pabellón. Confirmado que va aparte de la dirección técnica de La Rural. | D14: Sin cotizar | E14: USD | H14: =IF(F14="","",F14*(1+N(G14))) | I14: 1 | J14: =IF(OR(D14="Bonificado",D14="Reemplazado"),0,N(I14)*IF(H14="",N(K14),IF(E14="USD",H14,H14/TABLERO!$C$4))) | L14: =IF(D14="Alternativa","",J14-N(K14)) | M14: Pendiente de pedir presupuesto
A15: Subtotal Mobiliario | J15: =SUMIF($D$12:$D$14,"<>Alternativa",$J$12:$J$14) | K15: =SUM($K$12:$K$14) | L15: =J15-K15
A16: TÉCNICA
A17: Producción técnica | B17: Cerrado por Agustina | C17: Sonido, iluminación, video y LED. Cerrado en dólares. | D17: Cerrado | E17: USD | F17: 60000 | H17: =IF(F17="","",F17*(1+N(G17))) | I17: 1 | J17: =IF(OR(D17="Bonificado",D17="Reemplazado"),0,N(I17)*IF(H17="",N(K17),IF(E17="USD",H17,H17/TABLERO!$C$4))) | K17: 34000 | L17: =IF(D17="Alternativa","",J17-N(K17)) | M17: Negociación de Agustina · reemplaza la cotización vencida de Prina
A18: Entelado | B18: Cerrado por Agustina | C18: Entelado del pabellón. Negociado a la mitad de lo que estaba cotizado. | D18: Cerrado | E18: ARS | F18: 24500000 | H18: =IF(F18="","",F18*(1+N(G18))) | I18: 1 | J18: =IF(OR(D18="Bonificado",D18="Reemplazado"),0,N(I18)*IF(H18="",N(K18),IF(E18="USD",H18,H18/TABLERO!$C$4))) | L18: =IF(D18="Alternativa","",J18-N(K18)) | M18: Negociación de Agustina · US$16.000 aprox. al dólar de referencia
A19: Circuito cerrado (CCTV) | B19: Cerrado por Agustina | C19: Circuito cerrado de cámaras para el pabellón. | D19: Cerrado | E19: USD | F19: 6209 | H19: =IF(F19="","",F19*(1+N(G19))) | I19: 1 | J19: =IF(OR(D19="Bonificado",D19="Reemplazado"),0,N(I19)*IF(H19="",N(K19),IF(E19="USD",H19,H19/TABLERO!$C$4))) | L19: =IF(D19="Alternativa","",J19-N(K19)) | M19: Negociación de Agustina
A20: Bonificado por el proveedor de técnica | B20: Sin costo | C20: 500 vallas y efectos especiales, sin cargo. Es lo que evita el gasto de vallado que estaba presupuestado. | D20: Bonificado | E20: USD | H20: =IF(F20="","",F20*(1+N(G20))) | I20: 1 | J20: =IF(OR(D20="Bonificado",D20="Reemplazado"),0,N(I20)*IF(H20="",N(K20),IF(E20="USD",H20,H20/TABLERO!$C$4))) | L20: =IF(D20="Alternativa","",J20-N(K20)) | M20: Negociación de Agustina
A21: Subtotal Técnica | J21: =SUMIF($D$17:$D$20,"<>Alternativa",$J$17:$J$20) | K21: =SUM($K$17:$K$20) | L21: =J21-K21
A22: SERVICIOS
A23: Conectividad WiFi | B23: La Rural — Servicios de Conectividad | C23: 2 redes privadas de 30 Mbps (técnica + staff/acreditación), del 2 al 4 de octubre | D23: Cotizado | E23: ARS | F23: 1466063.8 | G23: 0.21 | H23: =IF(F23="","",F23*(1+N(G23))) | I23: 1 | J23: =IF(OR(D23="Bonificado",D23="Reemplazado"),0,N(I23)*IF(H23="",N(K23),IF(E23="USD",H23,H23/TABLERO!$C$4))) | K23: 800 | L23: =IF(D23="Alternativa","",J23-N(K23)) | M23: Mail conectividad@larural.com.ar 05/08/2026 · presupuesto N.º 2, base IPC junio (el del 16/06 era $1.438.728)
A24: Seguridad y vigilancia | B24: Road Seguridad S.A. | C24: 263 horas de vigilancia (armado, evento y desarme) + planos de evacuación $715.000 + supervisión general $795.000 | D24: Cotizado | E24: ARS | F24: 7218929 | G24: 0.21 | H24: =IF(F24="","",F24*(1+N(G24))) | I24: 1 | J24: =IF(OR(D24="Bonificado",D24="Reemplazado"),0,N(I24)*IF(H24="",N(K24),IF(E24="USD",H24,H24/TABLERO!$C$4))) | L24: =IF(D24="Alternativa","",J24-N(K24)) | M24: Mail presupuestos@roadseguridad.com.ar 12/08/2026 (versión V3, lista para firmar)
A25: Servicio médico | B25: Vittal — Socorro Médico Privado | C25: 1 UTIM TRI con dos médicos + enfermero/chofer, los tres días (2, 3 y 4 de octubre) | D25: Cotizado | E25: ARS | F25: 6366521.3 | G25: 0.105 | H25: =IF(F25="","",F25*(1+N(G25))) | I25: 1 | J25: =IF(OR(D25="Bonificado",D25="Reemplazado"),0,N(I25)*IF(H25="",N(K25),IF(E25="USD",H25,H25/TABLERO!$C$4))) | L25: =IF(D25="Alternativa","",J25-N(K25)) | M25: Mail vtomas@vittal.com.ar 28/08/2026 · tarifas actualizadas, sin consultorio
A26: Limpieza | B26: Higia Eventos | C26: 205,5 horas de limpieza: auditorio, baños y guardarropas, del 2 al 5 de octubre | D26: Cotizado | E26: ARS | F26: 3367440.9 | G26: 0.21 | H26: =IF(F26="","",F26*(1+N(G26))) | I26: 1 | J26: =IF(OR(D26="Bonificado",D26="Reemplazado"),0,N(I26)*IF(H26="",N(K26),IF(E26="USD",H26,H26/TABLERO!$C$4))) | L26: =IF(D26="Alternativa","",J26-N(K26)) | M26: Mail higiaeventos 22/06/2026 (reenviado 29/06) · 50% de anticipo antes del armado
A27: Retiro de residuos | B27: Gale Servicios | C27: Roll off con disposición final incluida. Cotización base abril 2026. | D27: Cotizado | E27: ARS | F27: 1471608.6 | G27: 0.21 | H27: =IF(F27="","",F27*(1+N(G27))) | I27: 1 | J27: =IF(OR(D27="Bonificado",D27="Reemplazado"),0,N(I27)*IF(H27="",N(K27),IF(E27="USD",H27,H27/TABLERO!$C$4))) | L27: =IF(D27="Alternativa","",J27-N(K27)) | M27: Mail higiaeventos 22/06/2026 (adjunto Gale) · se factura 100% por adelantado
A28: Baños químicos — ecobaños | B28: Sin cotizar | C28: Decidido: ecobaños, no los químicos tradicionales. Más limpios, mejor a la vista y ecofriendly. Falta pedir presupuesto. | D28: Sin cotizar | E28: USD | H28: =IF(F28="","",F28*(1+N(G28))) | I28: 1 | J28: =IF(OR(D28="Bonificado",D28="Reemplazado"),0,N(I28)*IF(H28="",N(K28),IF(E28="USD",H28,H28/TABLERO!$C$4))) | L28: =IF(D28="Alternativa","",J28-N(K28)) | M28: Decisión de Agustina · pendiente de cotizar
A29: Seguro de accidentes personales | B29: Chanes Seguros | C29: Cobertura MIA (muerte, invalidez y asistencia médica) para 150 personas, exigida por La Rural | D29: Cotizado | E29: ARS | F29: 953151.93 | H29: =IF(F29="","",F29*(1+N(G29))) | I29: 1 | J29: =IF(OR(D29="Bonificado",D29="Reemplazado"),0,N(I29)*IF(H29="",N(K29),IF(E29="USD",H29,H29/TABLERO!$C$4))) | K29: 400 | L29: =IF(D29="Alternativa","",J29-N(K29)) | M29: Mail nestor@chanesseguros.com.ar 13/07/2026 · premio único, cotizado para 15-19/07
A30: Subtotal Servicios | J30: =SUMIF($D$23:$D$29,"<>Alternativa",$J$23:$J$29) | K30: =SUM($K$23:$K$29) | L30: =J30-K30
A31: MERCH
A32: Pañuelos / pañoletas estampados (8.500) | B32: REMERASYESTAMPADOS | C32: Factura 2601012 del 20/06. Compra compartida Argentina + Uruguay: se imputa a Argentina el 65% (5.500 de 8.500 unidades, la misma proporcion que la grafica). El 50% ya esta abonado; el saldo se paga con la factura 2601019 por 5.276,51 USDT, de los cuales 3.429,73 son de Argentina. | D32: Contratado | E32: ARS | F32: 13387500 | G32: 0.21 | H32: =IF(F32="","",F32*(1+N(G32))) | I32: 0.65 | J32: =IF(OR(D32="Bonificado",D32="Reemplazado"),0,N(I32)*IF(H32="",N(K32),IF(E32="USD",H32,H32/TABLERO!$C$4))) | L32: =IF(D32="Alternativa","",J32-N(K32)) | M32: Drive · Presupuesto Pañuelos - Arg y Uru · facturas 2601012 (20/06) y 2601019 (16/08)
A33: Remeras premium estampadas (250) | B33: REMERASYESTAMPADOS | C33: Factura 2601017 del 16/08, $14.110 por unidad. Sube de 230 a 250 unidades contra la factura original 2601011, al mismo precio unitario. SIN PAGAR: se debe el 100% (2.780,64 USDT). | D33: Contratado | E33: ARS | F33: 3527500 | G33: 0.21 | H33: =IF(F33="","",F33*(1+N(G33))) | I33: 1 | J33: =IF(OR(D33="Bonificado",D33="Reemplazado"),0,N(I33)*IF(H33="",N(K33),IF(E33="USD",H33,H33/TABLERO!$C$4))) | L33: =IF(D33="Alternativa","",J33-N(K33)) | M33: Drive · Presupuestos camisetas + pañoletas · factura 2601017 (16/08)
A34: Bordado de gorras (940) | B34: REMERASYESTAMPADOS | C34: Bordado computarizado sobre las gorras que provee el cliente. Presupuesto del 03/07 con el descuento de $411.800 ya aplicado. Precio final, no lleva IVA. SIN PAGAR: se debe el 100% (1.721,95 USDT). | D34: Contratado | E34: ARS | F34: 2643200 | H34: =IF(F34="","",F34*(1+N(G34))) | I34: 1 | J34: =IF(OR(D34="Bonificado",D34="Reemplazado"),0,N(I34)*IF(H34="",N(K34),IF(E34="USD",H34,H34/TABLERO!$C$4))) | L34: =IF(D34="Alternativa","",J34-N(K34)) | M34: Drive · Presupuesto gorras (compra y bordado) / Bordado · factura 2601016 (10/08)
A35: Gorras Flex unicolor/bicolor (940) | B35: TEXTIL RYU S.R.L. | C35: Factura 2601009 del 20/06, pagada al 100% el 25/06. Es la compra de las gorras; el bordado va en su propia linea. | D35: Contratado | E35: ARS | F35: 2224980 | G35: 0.21 | H35: =IF(F35="","",F35*(1+N(G35))) | I35: 1 | J35: =IF(OR(D35="Bonificado",D35="Reemplazado"),0,N(I35)*IF(H35="",N(K35),IF(E35="USD",H35,H35/TABLERO!$C$4))) | K35: 5000 | L35: =IF(D35="Alternativa","",J35-N(K35)) | M35: Drive · Compra de gorras · factura 2601009 · hoja PAGOS del master
A36: Lanyards premium doble raso 25 mm (1.360) | B36: LEOTEX | C36: Sublimacion full print en ambas caras, 1.300 negros + 50 azules (la factura dice 1.360, la suma da 1.350: hay 10 de diferencia). Reemitida como 2601018 en USDT. OJO: la carpeta se llama "Nuevo pago - 50%" pero la factura viene por el total. | D36: Contratado | E36: ARS | F36: 2070600 | G36: 0.21 | H36: =IF(F36="","",F36*(1+N(G36))) | I36: 1 | J36: =IF(OR(D36="Bonificado",D36="Reemplazado"),0,N(I36)*IF(H36="",N(K36),IF(E36="USD",H36,H36/TABLERO!$C$4))) | L36: =IF(D36="Alternativa","",J36-N(K36)) | M36: Drive · Presupuesto Lanyards · facturas 2601013 (20/06) y 2601018 (16/08)
A37: Grafica oficial CMC — Argentina | B37: DERQUI IMPRESIONES | C37: 5.500 hojas A4, 5.500 tarjetas, 1.030 credenciales, 5.500 mapas y 1.000 bolsas de friselina. Reemitida el 16/08 para cambiar el medio de pago a USDT. | D37: Contratado | E37: ARS | F37: 3025260 | G37: 0.21 | H37: =IF(F37="","",F37*(1+N(G37))) | I37: 1 | J37: =IF(OR(D37="Bonificado",D37="Reemplazado"),0,N(I37)*IF(H37="",N(K37),IF(E37="USD",H37,H37/TABLERO!$C$4))) | L37: =IF(D37="Alternativa","",J37-N(K37)) | M37: Drive · Factura/presu ARGENTINA · factura 2601014 (20/06, reemitida 16/08)
A38: Grafica oficial CMC — Uruguay | B38: DERQUI IMPRESIONES | C38: NO ES DE ARGENTINA. 2.800 hojas A4, 2.800 tarjetas, 530 credenciales, 2.800 mapas y 1.000 bolsas de friselina, para el evento de Uruguay. Se deja a la vista en cero porque en la hoja PAGOS del master estaba cargada como Argentina: es el monto que no cerraba. | D38: Otro pais | E38: ARS | F38: 1564626 | G38: 0.21 | H38: =IF(F38="","",F38*(1+N(G38))) | I38: 0 | J38: =IF(OR(D38="Bonificado",D38="Reemplazado"),0,N(I38)*IF(H38="",N(K38),IF(E38="USD",H38,H38/TABLERO!$C$4))) | L38: =IF(D38="Alternativa","",J38-N(K38)) | M38: Drive · Factura/presu URUGUAY · factura 2601015 (20/06, reemitida 16/08)
A39: Cintas portacredencial (1.300) — alternativa | B39: Blocko | C39: Cinta raso 25 mm impresa a 4 colores dos caras + mosqueton zamak, $1.346 c/u. Es el MISMO item que los lanyards de LEOTEX, que ya esta contratado y con anticipo pagado. Estaba sumando dos veces: ahora queda como alternativa descartada. | D39: Alternativa | E39: ARS | F39: 1749800 | G39: 0.21 | H39: =IF(F39="","",F39*(1+N(G39))) | I39: 1 | J39: =IF(OR(D39="Bonificado",D39="Reemplazado"),0,N(I39)*IF(H39="",N(K39),IF(E39="USD",H39,H39/TABLERO!$C$4))) | L39: =IF(D39="Alternativa","",J39-N(K39)) | M39: Mail hola@blocko.com.ar 09/06/2026 · descartada contra la factura 2601013 de LEOTEX
A40: Marqueteria y enmarcado | B40: Sin cotizar | C40: Enmarcado de las certificaciones y los premios. Rubro nuevo, no estaba en ninguna planilla. | D40: Sin cotizar | E40: USD | H40: =IF(F40="","",F40*(1+N(G40))) | I40: 1 | J40: =IF(OR(D40="Bonificado",D40="Reemplazado"),0,N(I40)*IF(H40="",N(K40),IF(E40="USD",H40,H40/TABLERO!$C$4))) | L40: =IF(D40="Alternativa","",J40-N(K40)) | M40: Agregado por Agustina · pendiente de cotizar
A41: Cheques, escarapelas, diplomas, placas y manillas | B41: Sin cotizar | C41: Lo unico del merch que las facturas de Drive NO cubren. Las camisetas, los mapas, las bolsas y las credenciales ya estan facturados arriba. | D41: Sin cotizar | E41: USD | H41: =IF(F41="","",F41*(1+N(G41))) | I41: 1 | J41: =IF(OR(D41="Bonificado",D41="Reemplazado"),0,N(I41)*IF(H41="",N(K41),IF(E41="USD",H41,H41/TABLERO!$C$4))) | L41: =IF(D41="Alternativa","",J41-N(K41)) | M41: Pendiente de cotizar · antes estaba dentro del estimado global de US$8.689
...

Sheet TABLERO
A1: Argentina en una pantalla
A2: La Rural · Pabellón Azul · 3 y 4 de octubre de 2026
A4: Tipo de cambio (ARS por USD) | C4: 1510 | E4: Dólar con el que trabaja Agustina. Verificado contra dos de sus cifras: $900.000 de montaje = US$596 y $24.500.000 de entelado = US$16.225. Editá esta celda y se recalcula todo el libro.
A6: COSTO DEL EVENTO
A7: Costo total (cotizaciones reales + estimados) | C7: ='COSTOS UNIFICADOS'!J63 | E7: Suma de contratado, cotizado y lo que sólo tiene estimado. No incluye las alternativas descartadas.
A8: Lo que decía el presupuesto original | C8: ='COSTOS UNIFICADOS'!K63 | E8: Total de la hoja "Argentina (3 oct-4 oct)" del master: US$176.159.
A9: Diferencia contra el presupuesto | C9: ='COSTOS UNIFICADOS'!L63 | E9: Cuánto se corre el evento respecto de lo presupuestado, con los precios que hoy están sobre la mesa.
A11: COSTO POR PERSONA
A12: Base de cálculo | B12: Personas | C12: Costo por persona | E12: Qué incluye
A13: Aforo general | B13: 5000 | C13: =IFERROR($C$7/B13,"") | E13: Asistentes de entrada general según la hoja del master.
A14: VIP | B14: 1000 | C14: =IFERROR($C$7/B14,"") | E14: Asistentes VIP.
A15: Asistentes pagos (general + VIP) | B15: 6000 | C15: =IFERROR($C$7/B15,"") | E15: La base más útil para decidir el precio de la entrada.
A16: Mastermind del martes | B16: 246 | C16: =IFERROR($C$7/B16,"") | E16: Actividad aparte, no comparte la mayoría de los costos.
A17: Total de personas en el predio | B17: 6108 | C17: =IFERROR($C$7/B17,"") | E17: Asistentes pagos + 100 de staff + 8 del equipo interno.
A18: Las bases en amarillo son editables: cambiá el aforo y el costo por cabeza se recalcula.
A20: ESTADO DE LOS RUBROS
A21: Contratado (hay contrato o anticipo) | C21: =SUMIF('COSTOS UNIFICADOS'!$D:$D,"Contratado",'COSTOS UNIFICADOS'!$J:$J) | E21: Sede, las nueve facturas de merch e intercoms.
A22: Cotizado (hay presupuesto formal) | C22: =SUMIF('COSTOS UNIFICADOS'!$D:$D,"Cotizado",'COSTOS UNIFICADOS'!$J:$J) | E22: Sillas, WiFi, seguridad, servicio médico, limpieza, retiro de residuos y seguro.
A23: Sin cotizar (sólo estimado o nada) | C23: =SUMIF('COSTOS UNIFICADOS'!$D:$D,"Sin cotizar",'COSTOS UNIFICADOS'!$J:$J) | E23: Vuelos, alojamiento, ecobaños, marquetería, replanteo, unifilas, DJ, escoltas, Master Mind, personal logístico.
A24: Alternativas descartadas (no suman) | C24: =SUMIF('COSTOS UNIFICADOS'!$D:$D,"Alternativa",'COSTOS UNIFICADOS'!$J:$J)

Sheet MERCH
A1: Todo el merch, factura por factura
A2: Carpeta de Drive "Presupuestos merch" · facturas 2601009 a 2601019 · emisor IIDAI LLC. Los proveedores son argentinos, no colombianos.
A4: Proveedor | B4: Ítem | C4: Cant. | D4: Factura | E4: Fecha | F4: Neto (ARS) | G4: IVA | H4: Total (ARS) | I4: USDT de la factura | J4: País | K4: % Argentina | L4: Costo Argentina (USD) | M4: Falta pagar · regla 50% | N4: Falta pagar · según factura | O4: Nota
A5: REMERASYESTAMPADOS | B5: Pañuelos / pañoletas estampados | C5: 8.500 | D5: 2601012 → saldo 2601019 | E5: 20/06 → 16/08 | F5: 13387500 | G5: 0.21 | H5: =F5*(1+N(G5)) | I5: 5276.51 | J5: Argentina + Uruguay | K5: 0.65 | L5: =K5*H5/TABLERO!$C$4 | M5: =K5*5276.51 | N5: =K5*5276.51 | O5: La 2601019 ya viene emitida por el 50% restante. Falta definir con Uruguay como se reparte: aca se imputa el 65% a Argentina.
A6: REMERASYESTAMPADOS | B6: Remeras premium estampadas | C6: 250 | D6: 2601017 | E6: 16/08 | F6: 3527500 | G6: 0.21 | H6: =F6*(1+N(G6)) | I6: 2780.64 | J6: Argentina | K6: 1 | L6: =K6*H6/TABLERO!$C$4 | M6: =K6*2780.64 | N6: =K6*2780.64 | O6: Se debe el 100%. Sube de 230 a 250 unidades contra la factura original 2601011, al mismo precio unitario de $14.110.
A7: REMERASYESTAMPADOS | B7: Bordado computarizado en gorras | C7: 940 | D7: 2601016 | E7: 10/08 | F7: 2643200 | H7: =F7*(1+N(G7)) | I7: 1721.95 | J7: Argentina | K7: 1 | L7: =K7*H7/TABLERO!$C$4 | M7: =K7*1721.95 | N7: =K7*1721.95 | O7: Se debe el 100%. Precio final sin IVA, con el descuento de $411.800 ya aplicado. Las gorras las provee el cliente.
A8: TEXTIL RYU S.R.L. | B8: Gorra Flex unicolor/bicolor | C8: 940 | D8: 2601009 | E8: 20/06 | F8: 2224980 | G8: 0.21 | H8: =F8*(1+N(G8)) | J8: Argentina | K8: 1 | L8: =K8*H8/TABLERO!$C$4 | M8: =K8*0.0 | N8: =K8*0.0 | O8: Pagada al 100% el 25/06. Es la compra de la gorra, distinta del bordado.
A9: LEOTEX | B9: Lanyard premium doble raso 25 mm | C9: 1.360 | D9: 2601013 → 2601018 | E9: 20/06 → 16/08 | F9: 2070600 | G9: 0.21 | H9: =F9*(1+N(G9)) | I9: 1632.2 | J9: Argentina | K9: 1 | L9: =K9*H9/TABLERO!$C$4 | M9: =K9*816.1 | N9: =K9*1632.2 | O9: A CONFIRMAR: la carpeta se llama "Nuevo pago - 50%" pero la factura 2601018 viene por el total, igual que la original. El master registraba un saldo de US$850.
A10: DERQUI IMPRESIONES | B10: Grafica oficial CMC — Argentina | C10: — | D10: 2601014 | E10: 20/06 → 16/08 | F10: 3025260 | G10: 0.21 | H10: =F10*(1+N(G10)) | I10: 2384.73 | J10: Argentina | K10: 1 | L10: =K10*H10/TABLERO!$C$4 | M10: =K10*1192.37 | N10: =K10*2384.73 | O10: A CONFIRMAR: la reemision del 16/08 viene por el total. El master registraba un saldo de US$1.839 al 13/09.
A11: DERQUI IMPRESIONES | B11: Grafica oficial CMC — Uruguay | C11: — | D11: 2601015 | E11: 20/06 → 16/08 | F11: 1564626 | G11: 0.21 | H11: =F11*(1+N(G11)) | I11: 1233.35 | J11: Uruguay | K11: 0 | L11: =K11*H11/TABLERO!$C$4 | M11: =K11*616.68 | N11: =K11*1233.35 | O11: NO ES DE ARGENTINA. En la hoja PAGOS del master estaba cargada con pais = Argentina: es el monto que inflaba el total argentino.
A12: Blocko | B12: Cintas portacredencial (alternativa descartada) | C12: 1.300 | D12: presupuesto 09/06 | E12: 09/06 | F12: 1749800 | G12: 0.21 | H12: =F12*(1+N(G12)) | J12: Argentina | K12: 0 | L12: =K12*H12/TABLERO!$C$4 | M12: =K12*0.0 | N12: =K12*0.0 | O12: Es el mismo item que los lanyards de LEOTEX, que ya esta contratado. Estaba sumando dos veces en la version anterior de esta planilla.
B13: TOTAL IMPUTADO A ARGENTINA | L13: =SUM(L5:L12) | M13: =SUM(M5:M12) | N13: =SUM(N5:N12)
A15: CÓMO LEER LOS COLORES
A16: Verde — pagado al 100%: la compra de las gorras de Textil Ryu.
A17: Amarillo — 50% abonado, queda el saldo: pañuelos, lanyards y gráfica de Argentina.
A18: Rojo — sin pagar nada, se debe el 100%: las remeras y el bordado de las gorras.
A19: Gris — no suma al costo de Argentina: la gráfica de Uruguay y la cotización descartada de Blocko.
A21: LO QUE IBA A COSTAR CONTRA LO QUE COSTÓ
A22: Precios unitarios de merch.cmc2026.com al 06/07/2026, dólar $1.515. Compara el proveedor que traía Cumbre contra los proveedores argentinos que consiguió Agustina.
A23: Producto | B23: Cant. | C23: Unitario Cumbre | D23: Total Cumbre | E23: Unitario Agustina | F23: Total Agustina | G23: Ahorro | H23: Ahorro %
A24: ARGENTINA
A25: Remeras estampadas | B25: 100 | C25: 16.17 | D25: 1617.16 | E25: 9.31 | F25: 931.35 | G25: =D25-F25 | H25: =G25/D25
A26: Gorras negras | B26: 1.000 | C26: 9.9 | D26: 9900.99 | E26: 1.64 | F26: 1636.96 | G26: =D26-F26 | H26: =G26/D26
A27: Cinta colgante / lanyard | B27: 1.000 | C27: 1.25 | D27: 1247.52 | E27: 1 | F27: 1004.95 | G27: =D27-F27 | H27: =G27/D27
A28: Credenciales 10 × 13 cm | B28: 1.000 | C28: 0.57 | D28: 574.65 | E28: 0.48 | F28: 475.06 | G28: =D28-F28 | H28: =G28/D28
A29: Hojas A4 (contrato) | B29: 5.500 | C29: 0.2 | D29: 1107.26 | E29: 0.05 | F29: 265.31 | G29: =D29-F29 | H29: =G29/D29
A30: Tarjetas 21,5 × 10 cm (cheque) | B30: 5.500 | C30: 0.12 | D30: 671.62 | E30: 0.02 | F30: 109.78 | G30: =D30-F30 | H30: =G30/D30
A31: Bolsas de friselina, 2 colores | B31: 1.000 | C31: 1.14 | D31: 1141.91 | E31: 0.64 | F31: 644.55 | G31: =D31-F31 | H31: =G31/D31
A32: Pulseras tyvek — fuera de la comparación | B32: 5.500 | C32: 0.1 | D32: 544.55
A33: Subtotal Argentina | D33: =SUMIF($F$25:$F$32,"<>",D25:D32) | F33: =SUMIF($F$25:$F$32,"<>",F25:F32) | G33: =SUMIF($F$25:$F$32,"<>",G25:G32) | H33: =IFERROR(G33/D33,"")
A34: URUGUAY
A35: Mapas de niveles de consciencia | B35: 3.000 | C35: 0.254 | D35: 763 | E35: 0.089 | F35: 266.14 | G35: =D35-F35 | H35: =G35/D35
A36: Escarapelas / credenciales | B36: 600 | C36: 1.322 | D36: 793 | E36: 0.475 | F36: 285.03 | G36: =D36-F36 | H36: =G36/D36
A37: Contratos (hojas A4) | B37: 3.000 | C37: 0.153 | D37: 458 | E37: 0.048 | F37: 144.71 | G37: =D37-F37 | H37: =G37/D37
A38: Cheques (tarjetas) | B38: 3.000 | C38: 0.127 | D38: 382 | E38: 0.02 | F38: 59.88 | G38: =D38-F38 | H38: =G38/D38
A39: Cordones con mosquetón — fuera de la comparación | B39: 600 | C39: 1.5
A40: Subtotal Uruguay | D40: =SUMIF($F$35:$F$39,"<>",D35:D39) | F40: =SUMIF($F$35:$F$39,"<>",F35:F39) | G40: =SUMIF($F$35:$F$39,"<>",G35:G39) | H40: =IFERROR(G40/D40,"")
A41: TOTAL DE LA CANASTA — ARGENTINA + URUGUAY | D41: =D33+D40 | F41: =F33+F40 | G41: =G33+G40 | H41: =G41/D41
A43: La gorra sola explica la mitad del ahorro: el proveedor de Cumbre la cobraba US$9,90 y Agustina la consiguió a US$1,64. Sobre 1.000 unidades son US$8.264.
A44: Las pulseras tyvek quedan fuera de los dos lados de la cuenta porque no hay precio comparable del lado argentino.
...

Sheet PAGOS
A1: Cuánto se pagó, cuánto falta y cuándo
A2: Sólo lo que está documentado. Lo que no tiene fecha acordada va abajo, en el resto.
A4: Bloque | B4: Concepto | C4: Fecha | D4: USD | E4: Estado | F4: De dónde sale
A5: YA PAGADO
A6: Sede | B6: La Rural — anticipo del contrato | C6: 27/04/2026 | D6: 43446 | E6: Pagado | F6: Hoja PAGOS del master
A7: Producción | B7: Intercoms — 100% | C7: ya comprados | D7: 560 | E7: Pagado | F7: Confirmado por Agustina el 03/09
A8: Técnica | B8: Grupo MET — factura INV-11 | C8: 31/07/2026 | D8: 5000 | E8: Pagado | F8: Recibo de Mercury del 31/07
A9: Merch | B9: Pañuelos — 50% (parte Argentina) | C9: 24/06/2026 | D9: 3569.15 | E9: Pagado | F9: Master: 50% de US$10.982, imputado al 65%
A10: Merch | B10: Gorras — 100% | C10: 25/06/2026 | D10: 1825 | E10: Pagado | F10: Factura 2601009 de Textil Ryu
A11: Merch | B11: Lanyards — 50% | C11: 25/06/2026 | D11: 849 | E11: Pagado | F11: Hoja PAGOS del master
A12: Merch | B12: Gráfica Argentina — anticipo | C12: 25/06/2026 | D12: 642 | E12: Pagado | F12: Master: total US$2.481, saldo US$1.839
B13: Pagado a hoy | D13: =SUM(D6:D12)
A15: FALTA PAGAR · CON FECHA
A16: Sede | B16: La Rural — saldo, cuota 1 de 2 | C16: 24/08/2026 | D16: 15777 | E16: VENCIDA | F16: Cronograma del master
A17: Merch | B17: Remeras (250) | C17: ya facturado | D17: 2780.64 | E17: SIN PAGAR | F17: Factura 2601017 del 16/08 · NO figura en el master
A18: Merch | B18: Bordado de gorras (940) | C18: ya facturado | D18: 1721.95 | E18: SIN PAGAR | F18: Factura 2601016 del 10/08 · NO figura en el master
A19: Merch | B19: Pañuelos — saldo (parte Argentina) | C19: 13/09/2026 | D19: 3429.73 | E19: Programado | F19: Factura 2601019 · 65% de 5.276,51 USDT
A20: Merch | B20: Gráfica Argentina — saldo | C20: 13/09/2026 | D20: 1192.37 | E20: Programado | F20: Master. La factura 2601014 viene por el total: a confirmar
A21: Merch | B21: Lanyards — saldo | C21: 13/09/2026 | D21: 816.1 | E21: Programado | F21: Master. La factura 2601018 viene por el total: a confirmar
A22: Sede | B22: La Rural — saldo, cuota 2 de 2 | C22: 23/09/2026 | D22: 15777 | E22: Programado | F22: Cronograma del master
B23: Comprometido con fecha | D23: =SUM(D16:D22)
B24: De eso, vencido o facturado sin pagar | D24: =SUMIF(E16:E22,"VENCIDA",D16:D22)+SUMIF(E16:E22,"SIN PAGAR",D16:D22)
A26: RESUMEN
B27: Costo total del evento | D27: ='COSTOS UNIFICADOS'!J63
B28: Ya pagado | D28: =D13
B29: Falta desembolsar | D29: ='COSTOS UNIFICADOS'!J63-D13
B30: de eso, con fecha acordada | D30: =D23
B31: de eso, todavía sin fecha | D31: ='COSTOS UNIFICADOS'!J63-D13-D23
B33: Las remeras y el bordado de gorras están facturados desde agosto y no figuran en el cronograma del master: son US$4.503 que hoy no están en ningún calendario.
B34: El resto sin fecha son los rubros cerrados y cotizados que todavía no tienen forma de pago acordada: técnica, entelado, CCTV, catering, sillas y los servicios del predio.
B35: Las facturas reemitidas de LEOTEX y Derqui vienen por el total aunque el master registra el 50% abonado. Acá se tomó la regla del 50%: si las facturas están bien, son US$2.008 más.

Sheet DECISIONES
A1: Decisiones abiertas que mueven el número
A2: Cada fila cambia el costo total. Ordenadas por cuánto pesan.
A4: Decisión | B4: Opción A | C4: Opción B | D4: Diferencia | E4: Qué hay que hacer
A5: Infraestructura de La Rural | B5: Presupuesto completo: $66.494.708 (US$43.461), con las 5.000 sillas y todo el mobiliario | C5: Sólo panelería + dirección técnica + guardias: $16.858.366 (US$11.019). El mobiliario se compra aparte. | D5: =(66494708.2-16858366.2)/TABLERO!$C$4 | E5: Agustina marca ítem por ítem qué se queda. La hoja INFRAESTRUCTURA tiene las 28 líneas del presupuesto para filtrar.
A6: Montaje de las sillas | B6: La Rural con las sillas incluidas y armadas | C6: FDL Eventos + montaje/acomodación/desmontaje negociado en $900.000 | E6: Con FDL a $31.218.000 más $900.000 de montaje son US$20.992 contra US$27.778 de La Rural. Cerrar el número del montaje y firmar.
A7: Catering — cerrado | B7: Grupo Ambient: US$14.569 por las dos propuestas | C7: La planilla tenía US$33.820 estimados | D7: =14569-33820 | E7: Cerrado: 600 desayunos VIP (no 800) + comidas para 150 personas. US$19.251 por debajo de lo presupuestado. OJO: la factura 2601021 está calculada sobre 800 desayunos; pedirle a Ángeles que la reemita por 600 antes de pagar el anticipo.
A8: Rubros nuevos sin cotizar | B8: Ecobaños, marquetería de certificaciones y premios, replanteo de sillas con ingeniero | C8: Hoy entran en US$0 | E8: Pedir las tres cotizaciones esta semana. Son los últimos huecos que quedan además de vuelos y alojamiento.
A9: Merch — el 50% que falta pagar | B9: Regla del 50%: quedan US$9.941 por transferir en USDT | C9: Según las facturas reemitidas en agosto: US$11.949 | D9: =11949.25-9940.79 | E9: Las facturas de LEOTEX (lanyards) y Derqui (gráfica ARG) vienen por el total aunque ya se abonó el 50%. Una consulta a cada proveedor cierra la diferencia. Lo urgente igual son las remeras (US$2.781) y el bordado de gorras (US$1.722): esos no tienen nada pagado.
A10: Merch — cómo se reparten los pañuelos con Uruguay | B10: Los 8.500 pañuelos se imputan 65% a Argentina (US$6.973) | C10: Si van todos a Argentina: US$10.728 | D10: =0.35*13387500*1.21/TABLERO!$C$4 | E10: La factura no separa las unidades por país. Definir el reparto con Uruguay antes de cerrar el número para el CEO.
A11: Vuelos y alojamiento del equipo | B11: Sin cotizar | C11: Sin cotizar | E11: No hay ni un mail ni una línea en el sheet. Con 8 personas de equipo interno, es el hueco más grande que queda.
A12: Facturación al exterior | B12: FDL Eventos y Vittal no confirmaron si pueden facturar a la empresa de EE.UU. | C12: Buscar proveedores que sí facturen, o resolver un circuito de pago local | E12: Resolverlo antes de firmar: puede trabar los dos contratos.

Sheet AHORROS
A1: Lo cotizado contra lo que se cerró
A2: Cuánto se bajó rubro por rubro. La columna "Respaldo" dice si la referencia está documentada en el correo o si es un dato aportado.
A4: Rubro | B4: Referencia cotizada | C4: Ref. en pesos | D4: Ref. USD | E4: Lo que se cerró | F4: Cerrado en pesos | G4: Cerrado USD | H4: Ahorro USD | I4: Ahorro % | J4: Respaldo
A5: Infraestructura — armado de stands | B5: La Rural: panelería + dirección técnica + guardias | C5: 16858366 | D5: =C5/TABLERO!$C$4 | E5: Armado del stand de staff, el de producción y el camarín | G5: 9270 | H5: =D5-G5 | I5: =IFERROR(H5/D5,"") | J5: Presupuesto de La Rural del 17/08 (mail criccio@larural.com.ar): panelería $9.938.187 más generales $6.920.179. Cerrado por Agustina en US$9.270.
A6: Mobiliario — sillas y montaje | B6: La Rural: 5.000 sillas imperio bordó, armado incluido | D6: 28431 | E6: FDL Eventos: 5.500 sillas + flete, más el montaje, la acomodación y el desmontaje | G6: 17450 | H6: =D6-G6 | I6: =IFERROR(H6/D6,"") | J6: Cifras de Agustina, sin IVA. Reemplaza la fila que estaba aparte como "sillas": es la misma negociación, estaba contada dos veces. Verificado: 17.450 al dólar de referencia son $26.698.500, que es el presupuesto FDL 026-2697 ($25.800.000) más los $900.000 del montaje. Agustina tiene los presupuestos anteriores para adjuntar.
A7: Entelado | B7: Primer presupuesto recibido | D7: 25490 | E7: Negociado por Agustina | G7: 16500 | H7: =D7-G7 | I7: =IFERROR(H7/D7,"") | J7: Cifras de Agustina, sin IVA. Verificado: 25.490 al dólar de referencia son $39.000.000 exactos, que es la primera cotización. Agustina tiene el presupuesto anterior para adjuntar.
A8: Catering | B8: Primera propuesta de Grupo Ambient | C8: 30000000 | D8: =C8/TABLERO!$C$4 | E8: 600 lunchbox VIP + desayuno, almuerzo y cena para 150 personas | G8: 14569 | H8: =D8-G8 | I8: =IFERROR(H8/D8,"") | J8: Cierre informado por Agustina. En el correo está la propuesta de AmbientHouse del 16/06 a $28.500 + IVA por persona por día con base mínima de 480.
A9: Merch e impresos | B9: Proveedor de Cumbre, precios unitarios al 06/07 | D9: 16261.12 | E9: Proveedores argentinos conseguidos por Agustina | G9: 5067.97 | H9: =D9-G9 | I9: =IFERROR(H9/D9,"") | J9: Comparativa de merch.cmc2026.com al 06/07/2026 (dólar $1.515). Es una canasta cerrada de siete ítems: remeras, gorras, lanyards, credenciales, hojas A4, tarjetas y bolsas de friselina. Las pulseras tyvek quedan fuera de los dos lados porque no hay precio comparable. NO es el total del rubro merch: los pañuelos y el bordado de gorras no entran en esta comparación.
A10: Vallado del público | B10: Presupuestado en la hoja de Argentina | D10: 1250 | E10: 500 vallas bonificadas por el proveedor de técnica | G10: 0 | H10: =D10-G10 | I10: =IFERROR(H10/D10,"") | J10: Negociación de Agustina. Además bonifican los efectos especiales, que no estaban valorizados.
A11: AHORRO TOTAL | D11: =SUM(D5:D10) | G11: =SUM(G5:G10) | H11: =SUM(H5:H10)
A13: TÉCNICA — la comparación no es directa
A14: Se pidió cotización de técnica a NUEVE empresas el 13 y 14 de junio. Respondieron seis con número. El detalle completo está en la hoja COTIZACIONES TÉCNICA.
A16: · Sound-Light (16/06): el PDF no se pudo abrir, el mail pesa 33 MB. El mail del 19/06 les dice que las otras estaban "prácticamente la mitad", lo que lo ubica por encima de los $100.000.000.
A17: · Bonetto (17/06): $94.936.000 — sonido e iluminación $69.736.000, LED $20.720.000, CCTV $4.480.000. Grúas y efectos aparte (la chispa fría la cobra POR MINUTO).
A18: · Prina (18/06): $48.885.000 + IVA = $59.150.850. Pero cotiza 40 m² de LED cuando el rider pide 65, y deja afuera grúas y energía. Vencida.
A19: · 2MG (24/06): $45.000.000 con descuento + IVA = $54.450.000, más $19.202.700 de adicionales. Sonido más liviano, cotizado para "2000 / 5000 pax".
A20: · Dixi Group (26/06): $82.000.000 + IVA = $99.220.000 llave en mano, con rigging completo, encomiendas y 4 máquinas de chispa fría.
A21: · VMG (29/06): $15.276.250 con IVA, sólo las pantallas LED de 65 m².
A23: POR QUÉ TÉCNICA NO ENTRA EN LA TABLA DE ARRIBA: Grupo MET cerró en US$60.000 ($90.600.000) y con el circuito cerrado el paquete queda cerca de $100.000.000.
A24: Eso es prácticamente lo mismo que Dixi llave en mano y menos que Bonetto, pero está POR ENCIMA de 2MG y de Prina. Poner esa diferencia como ahorro no se sostendría
A25: delante del CEO, porque los alcances no son iguales: Prina cotizó 38% menos de LED, 2MG un sonido más chico, y Grupo MET incluye lo que se agregó tras la visita al predio.
A27: LO QUE SÍ SE SOSTIENE EN TÉCNICA: las 500 vallas y los efectos especiales van bonificados. Bonetto los cobra: $300.000 la máquina de humo y $600.000 POR MINUTO las dos de chispa fría.
... A30: FALTA UNA SOLA COSA para cerrar el ahorro de técnica con un número: el PDF de Grupo MET con el alcance final. Es el único de los siete proveedores sin presupuesto escrito en el correo.

Sheet COTIZACIONES TÉCNICA
A1: Las siete propuestas de técnica que llegaron
A2: Se pidió cotización a nueve empresas entre el 13 y el 14 de junio. Respondieron seis con número; Black-Out y 4A Latam nunca contestaron y una dirección rebotó.
A4: Proveedor | B4: Fecha | C4: Contacto | D4: Sin IVA | E4: Con IVA 21% | F4: USD al dólar de trabajo | G4: Qué incluye | H4: Qué queda aparte | I4: Observaciones
A5: Sound-Light | B5: 16/06/2026 | C5: ventas@sound-light.com.ar (Noelia Escudero) | F5: =IF(E5="","",E5/TABLERO!$C$4) | G5: Técnica integral sobre el pliego base. | H5: Sin detalle: no se pudo abrir el adjunto. | I5: El mail pesa 33 MB y el PDF no se puede extraer desde acá. Lo que sí está documentado es el mail del 19/06 en el que Agustina les dice que las otras cotizaciones estaban "prácticamente la mitad de lo cotizado por ustedes". Sobre las de esa fecha (Bonetto y Prina) eso lo ubica por encima de los $100.000.000.
A6: Bonetto Sonido e Iluminación | B6: 17/06/2026 | C6: cristian@bonetto.net | D6: 94936000 | E6: =D6*1.21 | F6: =IF(E6="","",E6/TABLERO!$C$4) | G6: Sonido e iluminación $69.736.000 · pantallas LED $20.720.000 · CCTV $4.480.000. 16 L-Acoustics Kiva II, 240 LED ST18-15, 322 truss box, consola Yamaha QL5. | H6: Grúas (2 autoelevadores tijera x 3 días) $4.480.000 · máquina de humo $300.000 · 2 máquinas de chispa fría $600.000 POR MINUTO · minuto adicional $150.000. | I6: Presupuesto PR26-287 V.1. El PDF viene con el texto vectorizado: hubo que renderizarlo a imagen para leerlo. No aclara si los valores llevan IVA. Dice expresamente "NO CONTEMPLA RIDER DE BANDA".
A7: Prina | B7: 18/06/2026 | C7: valentin.andina@prina.net | D7: 48885000 | E7: 59150850 | F7: =IF(E7="","",E7/TABLERO!$C$4) | G7: LED 40 m² $6.700.000 · CCTV 2 cámaras $4.510.000 · sonido (16 Adamson Y10) $10.465.000 · iluminación $12.490.000 · RRHH y logística $14.720.000. | H7: Incluye 2 máquinas Sparkular y máquina de humo. | I7: OJO CON EL ALCANCE: cotiza 40 m² de LED (6×4 + 2 de 2×4) cuando el rider pide 65 m² (7×5 + 2 de 3×5). No incluye grúas, brazos articulados ni tijeras, ni la generación de energía. Validez de 10 días: vencida desde el 28/06.
A8: 2MG | B8: 24/06/2026 | C8: rocio.g@2mg.net | D8: 45000000 | E8: 54450000 | F8: =IF(E8="","",E8/TABLERO!$C$4) | G8: Sonido, video (LED 65 m², medida correcta), iluminación, CCTV, efectos especiales, RRHH y logística. Total de lista $53.655.470, con descuento especial $45.000.000. | H8: Extras de iluminación $10.177.500 · escenario 13×3 m con pasarela $5.692.500. Los dos juntos suman $15.870.000 sin IVA. | I8: Incluye certificación de planos por escribano, eléctrico matriculado y autoelevadora, hasta 8 puntos de colgado. El sonido es más liviano que el de los otros (12 gabinetes DVA T8) y el presupuesto dice "2000 / 5000 pax". Validez 15 días.
A9: Dixi Group | B9: 26/06/2026 | C9: g.judcovski@dixieventos.com.ar | D9: 82000000 | E9: 99220000 | F9: =IF(E9="","",E9/TABLERO!$C$4) | G9: Llave en mano: sonido, iluminación (90 par LED, 6 beam, 8 wash), video (LED 65 m²), CCTV y rigging completo (6 puentes de 12 m, 14 aparejos de 1 T, motores). | H9: Nada: es llave en mano. | I9: Es el alcance más completo de todos. Incluye 4 máquinas de chispa fría con 8 disparos por día, plano general con puntos de colgado firmado por arquitecto, encomienda eléctrica de profesional matriculado y productores generales de técnica.
A10: VMG Visual Solutions | B10: 29/06/2026 | C10: presupuestos@vmg-web.com | D10: 12625000 | E10: 15276250 | F10: =IF(E10="","",E10/TABLERO!$C$4) | G10: Sólo pantallas LED: 65 m² (7×5 central + 2 de 3×5), pitch 2.6 indoor blackface, con control, servidor y operador. | H10: Todo lo demás. | I10: NO ES COMPARABLE con las otras: es únicamente video. Sirve para poner precio al renglón de LED. No incluye estructuras de colgado, rigging, tarimas, entelados ni autoelevadores. Recotiza si el dólar salta más de 15%.
A11: Grupo MET — ES EL QUE SE CONTRATÓ | B11: sin PDF | C11: lalo@somosgrupomet.com | E11: 90600000 | F11: =IF(E11="","",E11/TABLERO!$C$4) | G11: Sonido, iluminación, video y LED por US$60.000. Aparte: entelado $24.500.000 y circuito cerrado US$6.209. | H11: Bonifica 500 vallas y los efectos especiales, que en las otras cotizaciones se pagan. | I11: ES EL ÚNICO DE LOS SIETE SIN PRESUPUESTO ESCRITO EN EL CORREO. Se revisó todo el Gmail: en el hilo con Lalo Aizenberg hay ocho idas y vueltas entre el 16 y el 30 de junio y una visita al predio el 30/06, pero nunca llegó un PDF. Lo único que hay es la factura INV-11 de Mercury por US$5.000, pagada el 31/07.
A13: CÓMO LEER ESTA TABLA — Y POR QUÉ NO SE PUEDE RESTAR SIN MÁS
A14: Los siete números NO cotizan lo mismo, así que la diferencia contra Grupo MET no es un ahorro hasta que se iguale el alcance:
A15: · Grupo MET cerró en US$60.000 (unos $90.600.000) por sonido, iluminación, video y LED, con todo lo que se fue agregando después de la visita al predio del 30 de junio.
A16: · Sumándole el circuito cerrado (US$6.209) el paquete de técnica queda cerca de los $100.000.000, que es prácticamente lo mismo que cotizó Dixi llave en mano ($99.220.000) y por debajo de Bonetto ($114.872.560 más grúas y efectos).
A17: · En cambio queda POR ENCIMA de 2MG con descuento ($54.450.000 más $19.202.700 de adicionales = $73.652.700) y de Prina ($59.150.850).
A18: · Pero Prina cotizó 40 m² de LED cuando el rider pide 65, y dejó afuera las grúas y la energía; y 2MG cotizó un sonido más liviano, para "2000 / 5000 pax".
A20: Lo que sí está documentado y se sostiene solo:
A21: · Sound-Light quedó afuera por precio, y hay un mail del 19/06 pidiéndoles que revisen porque las otras estaban "prácticamente la mitad".
A22: · Los efectos especiales y las 500 vallas los bonifica Grupo MET. Bonetto los cobra: $300.000 la máquina de humo y $600.000 POR MINUTO las dos de chispa fría.
A23: · Se pidieron nueve cotizaciones y se compararon seis. Ese trabajo está entero en el correo.
A25: PARA CERRAR EL AHORRO DE TÉCNICA FALTA UNA SOLA COSA: el PDF de Grupo MET con el alcance final. Con eso se puede comparar contra el mismo alcance en Dixi, Bonetto, 2MG y Prina, y recién ahí poner un número.

Sheet INFRAESTRUCTURA
A1: Presupuesto de infraestructura de La Rural, línea por línea
A2: Las 28 líneas del PDF del 17/08. Marcá SÍ o NO en la columna "¿Se queda?" y el subtotal se recalcula.
A4: # | B4: Bloque | C4: Ítem | D4: Precio (ARS) | E4: USD | F4: ¿Se queda? | G4: Si se queda (ARS) | H4: Nota
A5: PANELERÍA (montaje de estructuras)
A6: 1 | B6: PANELERÍA (montaje de estructuras) | C6: Oficina de producción — 25 m² (panelería + puerta + iluminación) | D6: 1314575 | E6: =D6/TABLERO!$C$4 | F6: SÍ | G6: =IF(F6="SÍ",D6,0)
A7: 2 | B7: PANELERÍA (montaje de estructuras) | C7: Sala de staff — 100 m² (panelería + puerta + iluminación) | D7: 5258300 | E7: =D7/TABLERO!$C$4 | F7: SÍ | G7: =IF(F7="SÍ",D7,0)
A8: 3 | B8: PANELERÍA (montaje de estructuras) | C8: Depósito 8×8 para las 2.500 barras — 64 m² | D8: 3365312 | E8: =D8/TABLERO!$C$4 | F8: SÍ | G8: =IF(F8="SÍ",D8,0) | H8: Depósito para las 2.500 barras de la dinámica.
A9: MOBILIARIO · oficina de producción
A10: 4 | B10: oficina de producción | C10: Mesa redonda 1,60 ×2 | D10: 236000 | E10: =D10/TABLERO!$C$4 | F10: NO | G10: =IF(F10="SÍ",D10,0)
A11: 5 | B11: oficina de producción | C11: Silla imperio bordó ×10 | D11: 85000 | E11: =D11/TABLERO!$C$4 | F11: NO | G11: =IF(F11="SÍ",D11,0)
A12: 6 | B12: oficina de producción | C12: Sillón Valencia 2C ×2 | D12: 254000 | E12: =D12/TABLERO!$C$4 | F12: NO | G12: =IF(F12="SÍ",D12,0)
A13: 7 | B13: oficina de producción | C13: Sillón BRNO ×2 | D13: 160000 | E13: =D13/TABLERO!$C$4 | F13: NO | G13: =IF(F13="SÍ",D13,0)
A14: 8 | B14: oficina de producción | C14: Mesa ratona ×1 | D14: 118000 | E14: =D14/TABLERO!$C$4 | F14: NO | G14: =IF(F14="SÍ",D14,0)
A15: 9 | B15: oficina de producción | C15: Perchero de pie ×1 | D15: 40000 | E15: =D15/TABLERO!$C$4 | F15: NO | G15: =IF(F15="SÍ",D15,0)
A16: 10 | B16: oficina de producción | C16: Tacho de basura grande ×1 | D16: 56300 | E16: =D16/TABLERO!$C$4 | F16: NO | G16: =IF(F16="SÍ",D16,0)
A17: MOBILIARIO · sala de staff
A18: 11 | B18: sala de staff | C18: Mesa redonda 1,60 ×5 | D18: 590000 | E18: =D18/TABLERO!$C$4 | F18: NO | G18: =IF(F18="SÍ",D18,0)
A19: 12 | B19: sala de staff | C19: Silla imperio bordó ×40 | D19: 340000 | E19: =D19/TABLERO!$C$4 | F19: NO | G19: =IF(F19="SÍ",D19,0)
A20: 13 | B20: sala de staff | C20: Perchero de pie ×1 | D20: 40000 | E20: =D20/TABLERO!$C$4 | F20: NO | G20: =IF(F20="SÍ",D20,0)
A21: 14 | B21: sala de staff | C21: Tacho de basura grande ×1 | D21: 56300 | E21: =D21/TABLERO!$C$4 | F21: NO | G21: =IF(F21="SÍ",D21,0)
A22: MOBILIARIO · sala principal
A23: 15 | B23: sala principal | C23: Silla imperio bordó ×5.000 | D23: 42500000 | E23: =D23/TABLERO!$C$4 | F23: NO | G23: =IF(F23="SÍ",D23,0) | H23: Reemplazadas por las 5.500 sillas de FDL Eventos.
A24: 16 | B24: sala principal | C24: Mesa 1,80 × 0,90 ×40 | D24: 2500000 | E24: =D24/TABLERO!$C$4 | F24: NO | G24: =IF(F24="SÍ",D24,0)
A25: 17 | B25: sala principal | C25: Mantel ×40 | D25: 900000 | E25: =D25/TABLERO!$C$4 | F25: NO | G25: =IF(F25="SÍ",D25,0)
A26: 18 | B26: sala principal | C26: Mantel redondo ×8 | D26: 256000 | E26: =D26/TABLERO!$C$4 | F26: NO | G26: =IF(F26="SÍ",D26,0)
A27: MOBILIARIO · camarín de speakers
A28: 19 | B28: camarín de speakers | C28: Mesa redonda 1,60 ×1 | D28: 118000 | E28: =D28/TABLERO!$C$4 | F28: NO | G28: =IF(F28="SÍ",D28,0)
A29: 20 | B29: camarín de speakers | C29: Espejo ×1 | D29: 79500 | E29: =D29/TABLERO!$C$4 | F29: NO | G29: =IF(F29="SÍ",D29,0)
A30: 21 | B30: camarín de speakers | C30: Juego de living (sillones + mesa ratona) | D30: 1103642 | E30: =D30/TABLERO!$C$4 | F30: NO | G30: =IF(F30="SÍ",D30,0) | H30: El mobiliario "más fino" del camarín: candidato a contratárselo a La Rural.
A31: 22 | B31: camarín de speakers | C31: Perchero de pie ×1 | D31: 40000 | E31: =D31/TABLERO!$C$4 | F31: NO | G31: =IF(F31="SÍ",D31,0)
A32: 23 | B32: camarín de speakers | C32: Tacho de basura grande ×1 | D32: 56300 | E32: =D32/TABLERO!$C$4 | F32: NO | G32: =IF(F32="SÍ",D32,0)
A33: MOBILIARIO · escenario y técnica
A34: 24 | B34: escenario y técnica | C34: Mesa cocktail alta (escenario) ×1 | D34: 45000 | E34: =D34/TABLERO!$C$4 | F34: NO | G34: =IF(F34="SÍ",D34,0)
A35: 25 | B35: escenario y técnica | C35: Mesa alta para DJ ×1 | D35: 62300 | E35: =D35/TABLERO!$C$4 | F35: NO | G35: =IF(F35="SÍ",D35,0)
A36: GENERALES
A37: 26 | B37: GENERALES | C37: Dirección técnica de todo el evento + replanteo | D37: 5149179.2 | E37: =D37/TABLERO!$C$4 | F37: SÍ | G37: =IF(F37="SÍ",D37,0) | H37: Ojo: el replanteo de sillas va aparte, con ingeniero propio.
A38: 27 | B38: GENERALES | C38: Guardia eléctrica × 2 días | D38: 865800 | E38: =D38/TABLERO!$C$4 | F38: SÍ | G38: =IF(F38="SÍ",D38,0)
A39: 28 | B39: GENERALES | C39: Guardia técnica × 2 días | D39: 905200 | E39: =D39/TABLERO!$C$4 | F39: SÍ | G39: =IF(F39="SÍ",D39,0)
C41: TOTAL del presupuesto de La Rural | D41: =SUM(D6:D39) | E41: =D41/TABLERO!$C$4
C42: Lo que se queda (marcado SÍ) | D42: =SUM(G6:G39) | E42: =D42/TABLERO!$C$4
...
