Workbook

Sheet COSTOS UNIFICADOS
A1: Todos los costos de Argentina, bloque por bloque
A2: Una fila por concepto. "Monto a usar" toma la cotización real cuando existe y el estimado del sheet cuando no.
A4: Rubro | B4: Proveedor | C4: Detalle | D4: Estado | E4: Moneda | F4: Monto sin IVA | G4: IVA | H4: Total moneda origen | I4: % Argentina | J4: Total USD | K4: Estimado del sheet (USD) | L4: Diferencia | M4: Fuente
A5: SEDE
A6: Alquiler Pabellón Azul | B6: La Rural (contrato CC-00957) | C6: Locación 2 días de evento + 1 día de montaje | D6: Contratado | E6: USD | F6: 75000 | H6: =IF(F6="","",F6*(1+N(G6))) | I6: 1 | J6: =IF(OR(D6="Bonificado",D6="Reemplazado"),0,N(I6)*IF(H6="",N(K6),IF(E6="USD",H6,H6/TABLERO!$C$4))) | K6: 70000 | L6: =IF(D6="Alternativa","",J6-N(K6)) | M6: Contrato CC-00957 · hoja PAGOS del master (US$43.446 abonados el 27/04)
A7: Subtotal Sede | J7: =SUMIF($D$6:$D$6,"<>Alternativa",$J$6:$J$6) | K7: =SUM($K$6:$K$6) | L7: =J7-K7
A8: INFRAESTRUCTURA
A9: Armado de stands | B9: La Rural — Jefatura de Infraestructura | C9: Armado del stand de staff (100 m²), el de producción (menos de 50 m²) y el mobiliario del camarín de speakers. Falta pedirles los espejos. Las sillas del público van en su propia línea. | D9: Cerrado | E9: USD | F9: 9270 | H9: =IF(F9="","",F9*(1+N(G9))) | I9: 1 | J9: =IF(OR(D9="Bonificado",D9="Reemplazado"),0,N(I9)*IF(H9="",N(K9),IF(E9="USD",H9,H9/TABLERO!$C$4))) | L9: =IF(D9="Alternativa","",J9-N(K9)) | M9: Definición de Agustina sobre el presupuesto de $66.494.708 del 17/08 · ver hoja AHORROS
A10: Subtotal Infraestructura | J10: =SUMIF($D$9:$D$9,"<>Alternativa",$J$9:$J$9) | K10: =SUM($K$9:$K$9) | L10: =J10-K10
A11: MOBILIARIO
A12: Sillas del público (5.500) | B12: FDL Eventos | C12: Presupuesto 026-2697, alquiler por 4 días: 1.000 sillas hotel caño gris tapizado negro ($7.000.000) + 4.500 sillas plásticas Munro reforzadas ($17.100.000) + flete ($1.700.000). NO incluye armado. | D12: Cotizado | E12: ARS | F12: 25800000 | G12: 0.21 | H12: =IF(F12="","",F12*(1+N(G12))) | I12: 1 | J12: =IF(OR(D12="Bonificado",D12="Reemplazado"),0,N(I12)*IF(H12="",N(K12),IF(E12="USD",H12,H12/TABLERO!$C$4))) | K12: 16500 | L12: =IF(D12="Alternativa","",J12-N(K12)) | M12: Presupuesto FDL Eventos N.º 026-2697 del 07/08/2026 · pendiente de resolver facturación al exterior
A13: Montaje, acomodación y desmontaje de sillas | B13: En negociación | C13: Montaje previo, acomodación el sábado a la noche después de la dinámica y desmontaje el domingo. | D13: En negociación | E13: ARS | F13: 900000 | H13: =IF(F13="","",F13*(1+N(G13))) | I13: 1 | J13: =IF(OR(D13="Bonificado",D13="Reemplazado"),0,N(I13)*IF(H13="",N(K13),IF(E13="USD",H13,H13/TABLERO!$C$4))) | L13: =IF(D13="Alternativa","",J13-N(K13)) | M13: Negociación de Agustina · cerrar el número antes de firmar las sillas
A14: Replanteo de sillas (ingeniero) | B14: Sin cotizar | C14: Replanteo del layout de sillas del pabellón. Confirmado que va aparte de la dirección técnica de La Rural. | D14: Sin cotizar | E14: USD | H14: =IF(F14="","",F14*(1+N(G14))) | I14: 1 | J14: =IF(OR(D14="Bonificado",D14="Reemplazado"),0,N(I14)*IF(H14="",N(K14),IF(E14="USD",H14,H14/TABLERO!$C$4))) | L14: =IF(D14="Alternativa","",J14-N(K14)) | M14: Pendiente de pedir presupuesto
A15: Subtotal Mobiliario | J15: =SUMIF($D$12:$D$14,"<>Alternativa",$J$12:$J$14) | K15: =SUM($K$12:$K$14) | L15: =J15-K15
A16: TÉCNICA
A17: Producción técnica | B17: Cerrado por Agustina | C17: Sonido, iluminación, video y LED. Cerrado en dólares. | D17: Cerrado | E17: USD | F17: 60000 | H17: =IF(F17="","",F17*(1+N(G17))) | I17: 1 | J17: =IF(OR(D17="Bonificado",D17="Reemplazado"),0,N(I17)*IF(H17="",N(K17),IF(E17="USD",H17,H17/TABLERO!$C$4))) | K17: 34000 | L17: =IF(D17="Alternativa","",J17-N(K17)) | M17: Negociación de Agustina · reemplaza la cotización vencida de Prina
A18: Entelado | B18: Cerrado por Agustina | C18: Entelado del pabellón. Negociado a la mitad de lo que estaba cotizado. | D18: Cerrado | E18: ARS | F18: 24500000 | H18: =IF(F18="","",F18*(1+N(G18))) | I18: 1 | J18: =IF(OR(D18="Bonificado",D18="Reemplazado"),0,N(I18)*IF(H18="",N(K18),IF(E18="USD",H18,H18/TABLERO!$C$4))) | L18: =IF(D18="Alternativa","",J18-N(K18)) | M18: Negociación de Agustina · US$16.000 aprox. al dólar de referencia
A19: Circuito cerrado (CCTV) | B19: Cerrado por Agustina | C19: Circuito cerrado de cámaras para el pabellón. | D19: Cerrado | E19: USD | F19: 6209 | H19: =IF(F19="","",F19*(1+N(G19))) | I19: 1 | J19: =IF(OR(D19="Bonificado",D19="Reemplazado"),0,N(I19)*IF(H19="",N(K19),IF(E19="USD",H19,H19/TABLERO!$C$4))) | L19: =IF(D19="Alternativa","",J19-N(K19)) | M19: Negociación de Agustina
A20: Bonificado por el proveedor de técnica | B20: Sin costo | C20: 500 vallas y efectos especiales, sin cargo. Es lo que evita el gasto de vallado que estaba presupuestado. | D20: Bonificado | E20: USD | H20: =IF(F20="","",F20*(1+N(G20))) | I20: 1 | J20: =IF(OR(D20="Bonificado",D20="Reemplazado"),0,N(I20)*IF(H20="",N(K20),IF(E20="USD",H20,H20/TABLERO!$C$4))) | L20: =IF(D20="Alternativa","",J20-N(K20)) | M20: Negociación de Agustina
A21: Subtotal Técnica | J21: =SUMIF($D$17:$D$20,"<>Alternativa",$J$17:$J$20) | K21: =SUM($K$17:$K$20) | L21: =J21-K21
A22: SERVICIOS
A23: Conectividad WiFi | B23: La Rural — Servicios de Conectividad | C23: 2 redes privadas de 30 Mbps (técnica + staff/acreditación), del 2 al 4 de octubre | D23: Cotizado | E23: ARS | F23: 1466063.8 | G23: 0.21 | H23: =IF(F23="","",F23*(1+N(G23))) | I23: 1 | J23: =IF(OR(D23="Bonificado",D23="Reemplazado"),0,N(I23)*IF(H23="",N(K23),IF(E23="USD",H23,H23/TABLERO!$C$4))) | K23: 800 | L23: =IF(D23="Alternativa","",J23-N(K23)) | M23: Mail conectividad@larural.com.ar 05/08/2026 · presupuesto N.º 2, base IPC junio (el del 16/06 era $1.438.728)
A24: Seguridad y vigilancia | B24: Road Seguridad S.A. | C24: 263 horas de vigilancia (armado, evento y desarme) + planos de evacuación $715.000 + supervisión general $795.000 | D24: Cotizado | E24: ARS | F24: 7218929 | G24: 0.21 | H24: =IF(F24="","",F24*(1+N(G24))) | I24: 1 | J24: =IF(OR(D24="Bonificado",D24="Reemplazado"),0,N(I24)*IF(H24="",N(K24),IF(E24="USD",H24,H24/TABLERO!$C$4))) | L24: =IF(D24="Alternativa","",J24-N(K24)) | M24: Mail presupuestos@roadseguridad.com.ar 12/08/2026 (versión V3, lista para firmar)
A25: Servicio médico | B25: Vittal — Socorro Médico Privado | C25: 1 UTIM TRI con dos médicos + enfermero/chofer, los tres días (2, 3 y 4 de octubre) | D25: Cotizado | E25: ARS | F25: 6366521.3 | G25: 0.105 | H25: =IF(F25="","",F25*(1+N(G25))) | I25: 1 | J25: =IF(OR(D25="Bonificado",D25="Reemplazado"),0,N(I25)*IF(H25="",N(K25),IF(E25="USD",H25,H25/TABLERO!$C$4))) | L25: =IF(D25="Alternativa","",J25-N(K25)) | M25: Mail vtomas@vittal.com.ar 28/08/2026 · tarifas actualizadas, sin consultorio
A26: Limpieza | B26: Higia Eventos | C26: 205,5 horas de limpieza: auditorio, baños y guardarropas, del 2 al 5 de octubre | D26: Cotizado | E26: ARS | F26: 3367440.9 | G26: 0.21 | H26: =IF(F26="","",F26*(1+N(G26))) | I26: 1 | J26: =IF(OR(D26="Bonificado",D26="Reemplazado"),0,N(I26)*IF(H26="",N(K26),IF(E26="USD",H26,H26/TABLERO!$C$4))) | L26: =IF(D26="Alternativa","",J26-N(K26)) | M26: Mail higiaeventos 22/06/2026 (reenviado 29/06) · 50% de anticipo antes del armado
A27: Retiro de residuos | B27: Gale Servicios | C27: Roll off con disposición final incluida. Cotización base abril 2026. | D27: Cotizado | E27: ARS | F27: 1471608.6 | G27: 0.21 | H27: =IF(F27="","",F27*(1+N(G27))) | I27: 1 | J27: =IF(OR(D27="Bonificado",D27="Reemplazado"),0,N(I27)*IF(H27="",N(K27),IF(E27="USD",H27,H27/TABLERO!$C$4))) | L27: =IF(D27="Alternativa","",J27-N(K27)) | M27: Mail higiaeventos 22/06/2026 (adjunto Gale) · se factura 100% por adelantado
A28: Baños químicos — ecobaños | B28: Sin cotizar | C28: Decidido: ecobaños, no los químicos tradicionales. Más limpios, mejor a la vista y ecofriendly. Falta pedir presupuesto. | D28: Sin cotizar | E28: USD | H28: =IF(F28="","",F28*(1+N(G28))) | I28: 1 | J28: =IF(OR(D28="Bonificado",D28="Reemplazado"),0,N(I28)*IF(H28="",N(K28),IF(E28="USD",H28,H28/TABLERO!$C$4))) | L28: =IF(D28="Alternativa","",J28-N(K28)) | M28: Decisión de Agustina · pendiente de cotizar
A29: Seguro de accidentes personales | B29: Chanes Seguros | C29: Cobertura MIA (muerte, invalidez y asistencia médica) para 150 personas, exigida por La Rural | D29: Cotizado | E29: ARS | F29: 953151.93 | H29: =IF(F29="","",F29*(1+N(G29))) | I29: 1 | J29: =IF(OR(D29="Bonificado",D29="Reemplazado"),0,N(I29)*IF(H29="",N(K29),IF(E29="USD",H29,H29/TABLERO!$C$4))) | K29: 400 | L29: =IF(D29="Alternativa","",J29-N(K29)) | M29: Mail nestor@chanesseguros.com.ar 13/07/2026 · premio único, cotizado para 15-19/07
A30: Subtotal Servicios | J30: =SUMIF($D$23:$D$29,"<>Alternativa",$J$23:$J$29) | K30: =SUM($K$23:$K$29) | L30: =J30-K30
A31: MERCH
A32: Pañuelos / pañoletas estampados (8.500) | B32: REMERASYESTAMPADOS | C32: Factura 2601012 del 20/06. Compra compartida Argentina + Uruguay: se imputa a Argentina el 65% (5.500 de 8.500 unidades, la misma proporcion que la grafica). El 50% ya esta abonado; el saldo se paga con la factura 2601019 por 5.276,51 USDT, de los cuales 3.429,73 son de Argentina. | D32: Contratado | E32: ARS | F32: 13387500 | G32: 0.21 | H32: =IF(F32="","",F32*(1+N(G32))) | I32: 0.65 | J32: =IF(OR(D32="Bonificado",D32="Reemplazado"),0,N(I32)*IF(H32="",N(K32),IF(E32="USD",H32,H32/TABLERO!$C$4))) | L32: =IF(D32="Alternativa","",J32-N(K32)) | M32: Drive · Presupuesto Pañuelos - Arg y Uru · facturas 2601012 (20/06) y 2601019 (16/08)
A33: Remeras premium estampadas (250) | B33: REMERASYESTAMPADOS | C33: Factura 2601017 del 16/08, $14.110 por unidad. Sube de 230 a 250 unidades contra la factura original 2601011, al mismo precio unitario. SIN PAGAR: se debe el 100% (2.780,64 USDT). | D33: Contratado | E33: ARS | F33: 3527500 | G33: 0.21 | H33: =IF(F33="","",F33*(1+N(G33))) | I33: 1 | J33: =IF(OR(D33="Bonificado",D33="Reemplazado"),0,N(I33)*IF(H33="",N(K33),IF(E33="USD",H33,H33/TABLERO!$C$4))) | L33: =IF(D33="Alternativa","",J33-N(K33)) | M33: Drive · Presupuestos camisetas + pañoletas · factura 2601017 (16/08)
A34: Bordado de gorras (940) | B34: REMERASYESTAMPADOS | C34: Bordado computarizado sobre las gorras que provee el cliente. Presupuesto del 03/07 con el descuento de $411.800 ya aplicado. Precio final, no lleva IVA. SIN PAGAR: se debe el 100% (1.721,95 USDT). | D34: Contratado | E34: ARS | F34: 2643200 | H34: =IF(F34="","",F34*(1+N(G34))) | I34: 1 | J34: =IF(OR(D34="Bonificado",D34="Reemplazado"),0,N(I34)*IF(H34="",N(K34),IF(E34="USD",H34,H34/TABLERO!$C$4))) | L34: =IF(D34="Alternativa","",J34-N(K34)) | M34: Drive · Presupuesto gorras (compra y bordado) / Bordado · factura 2601016 (10/08)
A35: Gorras Flex unicolor/bicolor (940) | B35: TEXTIL RYU S.R.L. | C35: Factura 2601009 del 20/06, pagada al 100% el 25/06. Es la compra de las gorras; el bordado va en su propia linea. | D35: Contratado | E35: ARS | F35: 2224980 | G35: 0.21 | H35: =IF(F35="","",F35*(1+N(G35))) | I35: 1 | J35: =IF(OR(D35="Bonificado",D35="Reemplazado"),0,N(I35)*IF(H35="",N(K35),IF(E35="USD",H35,H35/TABLERO!$C$4))) | K35: 5000 | L35: =IF(D35="Alternativa","",J35-N(K35)) | M35: Drive · Compra de gorras · factura 2601009 · hoja PAGOS del master
A36: Lanyards premium doble raso 25 mm (1.360) | B36: LEOTEX | C36: Sublimacion full print en ambas caras, 1.300 negros + 50 azules (la factura dice 1.360, la suma da 1.350: hay 10 de diferencia). Reemitida como 2601018 en USDT. OJO: la carpeta se llama "Nuevo pago - 50%" pero la factura viene por el total. | D36: Contratado | E36: ARS | F36: 2070600 | G36: 0.21 | H36: =IF(F36="","",F36*(1+N(G36))) | I36: 1 | J36: =IF(OR(D36="Bonificado",D36="Reemplazado"),0,N(I36)*IF(H36="",N(K36),IF(E36="USD",H36,H36/TABLERO!$C$4))) | L36: =IF(D36="Alternativa","",J36-N(K36)) | M36: Drive · Presupuesto Lanyards · facturas 2601013 (20/06) y 2601018 (16/08)
A37: Grafica oficial CMC — Argentina | B37: DERQUI IMPRESIONES | C37: 5.500 hojas A4, 5.500 tarjetas, 1.030 credenciales, 5.500 mapas y 1.000 bolsas de friselina. Reemitida el 16/08 para cambiar el medio de pago a USDT. | D37: Contratado | E37: ARS | F37: 3025260 | G37: 0.21 | H37: =IF(F37="","",F37*(1+N(G37))) | I37: 1 | J37: =IF(OR(D37="Bonificado",D37="Reemplazado"),0,N(I37)*IF(H37="",N(K37),IF(E37="USD",H37,H37/TABLERO!$C$4))) | L37: =IF(D37="Alternativa","",J37-N(K37)) | M37: Drive · Factura/presu ARGENTINA · factura 2601014 (20/06, reemitida 16/08)
A38: Grafica oficial CMC — Uruguay | B38: DERQUI IMPRESIONES | C38: NO ES DE ARGENTINA. 2.800 hojas A4, 2.800 tarjetas, 530 credenciales, 2.800 mapas y 1.000 bolsas de friselina, para el evento de Uruguay. Se deja a la vista en cero porque en la hoja PAGOS del master estaba cargada como Argentina: es el monto que no cerraba. | D38: Otro pais | E38: ARS | F38: 1564626 | G38: 0.21 | H38: =IF(F38="","",F38*(1+N(G38))) | I38: 0 | J38: =IF(OR(D38="Bonificado",D38="Reemplazado"),0,N(I38)*IF(H38="",N(K38),IF(E38="USD",H38,H38/TABLERO!$C$4))) | L38: =IF(D38="Alternativa","",J38-N(K38)) | M38: Drive · Factura/presu URUGUAY · factura 2601015 (20/06, reemitida 16/08)
A39: Cintas portacredencial (1.300) — alternativa | B39: Blocko | C39: Cinta raso 25 mm impresa a 4 colores dos caras + mosqueton zamak, $1.346 c/u. Es el MISMO item que los lanyards de LEOTEX, que ya esta contratado y con anticipo pagado. Estaba sumando dos veces: ahora queda como alternativa descartada. | D39: Alternativa | E39: ARS | F39: 1749800 | G39: 0.21 | H39: =IF(F39="","",F39*(1+N(G39))) | I39: 1 | J39: =IF(OR(D39="Bonificado",D39="Reemplazado"),0,N(I39)*IF(H39="",N(K39),IF(E39="USD",H39,H39/TABLERO!$C$4))) | L39: =IF(D39="Alternativa","",J39-N(K39)) | M39: Mail hola@blocko.com.ar 09/06/2026 · descartada contra la factura 2601013 de LEOTEX
A40: Marqueteria y enmarcado | B40: Sin cotizar | C40: Enmarcado de las certificaciones y los premios. Rubro nuevo, no estaba en ninguna planilla. | D40: Sin cotizar | E40: USD | H40: =IF(F40="","",F40*(1+N(G40))) | I40: 1 | J40: =IF(OR(D40="Bonificado",D40="Reemplazado"),0,N(I40)*IF(H40="",N(K40),IF(E40="USD",H40,H40/TABLERO!$C$4))) | L40: =IF(D40="Alternativa","",J40-N(K40)) | M40: Agregado por Agustina · pendiente de cotizar
A41: Cheques, escarapelas, diplomas, placas y manillas | B41: Sin cotizar | C41: Lo unico del merch que las facturas de Drive NO cubren. Las camisetas, los mapas, las bolsas y las credenciales ya estan facturados arriba. | D41: Sin cotizar | E41: USD | H41: =IF(F41="","",F41*(1+N(G41))) | I41: 1 | J41: =IF(OR(D41="Bonificado",D41="Reemplazado"),0,N(I41)*IF(H41="",N(K41),IF(E41="USD",H41,H41/TABLERO!$C$4))) | L41: =IF(D41="Alternativa","",J41-N(K41)) | M41: Pendiente de cotizar · antes estaba dentro del estimado global de US$8.689
...

Sheet TABLERO
A1: Argentina en una pantalla
A2: La Rural · Pabellón Azul · 3 y 4 de octubre de 2026
A4: Tipo de cambio (ARS por USD) | C4: 1510 | E4: Dólar con el que trabaja Agustina. Verificado contra dos de sus cifras: $900.000 de montaje = US$596 y $24.500.000 de entelado = US$16.225. Editá esta celda y se recalcula todo el libro.
A6: COSTO DEL EVENTO
A7: Costo total (cotizaciones reales + estimados) | C7: ='COSTOS UNIFICADOS'!J63 | E7: Suma de contratado, cotizado y lo que sólo tiene estimado. No incluye las alternativas descartadas.
A8: Lo que decía el presupuesto original | C8: ='COSTOS UNIFICADOS'!K63 | E8: Total de la hoja "Argentina (3 oct-4 oct)" del master: US$176.159.
A9: Diferencia contra el presupuesto | C9: ='COSTOS UNIFICADOS'!L63 | E9: Cuánto se corre el evento respecto de lo presupuestado, con los precios que hoy están sobre la mesa.
A11: COSTO POR PERSONA
A12: Base de cálculo | B12: Personas | C12: Costo por persona | E12: Qué incluye
A13: Aforo general | B13: 5000 | C13: =IFERROR($C$7/B13,"") | E13: Asistentes de entrada general según la hoja del master.
A14: VIP | B14: 1000 | C14: =IFERROR($C$7/B14,"") | E14: Asistentes VIP.
A15: Asistentes pagos (general + VIP) | B15: 6000 | C15: =IFERROR($C$7/B15,"") | E15: La base más útil para decidir el precio de la entrada.
A16: Mastermind del martes | B16: 246 | C16: =IFERROR($C$7/B16,"") | E16: Actividad aparte, no comparte la mayoría de los costos.
A17: Total de personas en el predio | B17: 6108 | C17: =IFERROR($C$7/B17,"") | E17: Asistentes pagos + 100 de staff + 8 del equipo interno.
A18: Las bases en amarillo son editables: cambiá el aforo y el costo por cabeza se recalcula.
A20: ESTADO DE LOS RUBROS
A21: Contratado (hay contrato o anticipo) | C21: =SUMIF('COSTOS UNIFICADOS'!$D:$D,"Contratado",'COSTOS UNIFICADOS'!$J:$J) | E21: Sede, las nueve facturas de merch e intercoms.
A22: Cotizado (hay presupuesto formal) | C22: =SUMIF('COSTOS UNIFICADOS'!$D:$D,"Cotizado",'COSTOS UNIFICADOS'!$J:$J) | E22: Sillas, WiFi, seguridad, servicio médico, limpieza, retiro de residuos y seguro.
A23: Sin cotizar (sólo estimado o nada) | C23: =SUMIF('COSTOS UNIFICADOS'!$D:$D,"Sin cotizar",'COSTOS UNIFICADOS'!$J:$J) | E23: Vuelos, alojamiento, ecobaños, marquetería, replanteo, unifilas, DJ, escoltas, Master Mind, personal logístico.
A24: Alternativas descartadas (no suman) | C24: =SUMIF('COSTOS UNIFICADOS'!$D:$D,"Alternativa",'COSTOS UNIFICADOS'!$J:$J)

Sheet PAGOS
A1: Cuánto se pagó, cuánto falta y cuándo
A2: Sólo lo que está documentado. Lo que no tiene fecha acordada va abajo, en el resto.
A4: Bloque | B4: Concepto | C4: Fecha | D4: USD | E4: Estado | F4: De dónde sale
A5: YA PAGADO
A6: Sede | B6: La Rural — anticipo del contrato | C6: 27/04/2026 | D6: 43446 | E6: Pagado | F6: Hoja PAGOS del master
A7: Producción | B7: Intercoms — 100% | C7: ya comprados | D7: 560 | E7: Pagado | F7: Confirmado por Agustina el 03/09
A8: Técnica | B8: Grupo MET — factura INV-11 | C8: 31/07/2026 | D8: 5000 | E8: Pagado | F8: Recibo de Mercury del 31/07
A9: Merch | B9: Pañuelos — 50% (parte Argentina) | C9: 24/06/2026 | D9: 3569.15 | E9: Pagado | F9: Master: 50% de US$10.982, imputado al 65%
A10: Merch | B10: Gorras — 100% | C10: 25/06/2026 | D10: 1825 | E10: Pagado | F10: Factura 2601009 de Textil Ryu
A11: Merch | B11: Lanyards — 50% | C11: 25/06/2026 | D11: 849 | E11: Pagado | F11: Hoja PAGOS del master
A12: Merch | B12: Gráfica Argentina — anticipo | C12: 25/06/2026 | D12: 642 | E12: Pagado | F12: Master: total US$2.481, saldo US$1.839
B13: Pagado a hoy | D13: =SUM(D6:D12)
A15: FALTA PAGAR · CON FECHA
A16: Sede | B16: La Rural — saldo, cuota 1 de 2 | C16: 24/08/2026 | D16: 15777 | E16: VENCIDA | F16: Cronograma del master
A17: Merch | B17: Remeras (250) | C17: ya facturado | D17: 2780.64 | E17: SIN PAGAR | F17: Factura 2601017 del 16/08 · NO figura en el master
A18: Merch | B18: Bordado de gorras (940) | C18: ya facturado | D18: 1721.95 | E18: SIN PAGAR | F18: Factura 2601016 del 10/08 · NO figura en el master
A19: Merch | B19: Pañuelos — saldo (parte Argentina) | C19: 13/09/2026 | D19: 3429.73 | E19: Programado | F19: Factura 2601019 · 65% de 5.276,51 USDT
A20: Merch | B20: Gráfica Argentina — saldo | C20: 13/09/2026 | D20: 1192.37 | E20: Programado | F20: Master. La factura 2601014 viene por el total: a confirmar
A21: Merch | B21: Lanyards — saldo | C21: 13/09/2026 | D21: 816.1 | E21: Programado | F21: Master. La factura 2601018 viene por el total: a confirmar
A22: Sede | B22: La Rural — saldo, cuota 2 de 2 | C22: 23/09/2026 | D22: 15777 | E22: Programado | F22: Cronograma del master
B23: Comprometido con fecha | D23: =SUM(D16:D22)
B24: De eso, vencido o facturado sin pagar | D24: =SUMIF(E16:E22,"VENCIDA",D16:D22)+SUMIF(E16:E22,"SIN PAGAR",D16:D22)
A26: RESUMEN
B27: Costo total del evento | D27: ='COSTOS UNIFICADOS'!J63
B28: Ya pagado | D28: =D13
B29: Falta desembolsar | D29: ='COSTOS UNIFICADOS'!J63-D13
B30: de eso, con fecha acordada | D30: =D23
B31: de eso, todavía sin fecha | D31: ='COSTOS UNIFICADOS'!J63-D13-D23
B33: Las remeras y el bordado de gorras están facturados desde agosto y no figuran en el cronograma del master: son US$4.503 que hoy no están en ningún calendario.
B34: El resto sin fecha son los rubros cerrados y cotizados que todavía no tienen forma de pago acordada: técnica, entelado, CCTV, catering, sillas y los servicios del predio.
B35: Las facturas reemitidas de LEOTEX y Derqui vienen por el total aunque el master registra el 50% abonado. Acá se tomó la regla del 50%: si las facturas están bien, son US$2.008 más.
