Workbook

Sheet CHECKLIST
A1: CHECKLIST DE PAGOS · ARGENTINA
A2: Cumbre de los Millonarios Conscientes 2026 · La Rural, Pabellón Azul · montaje 2 de octubre, evento 3 y 4 · corte al 2 de septiembre · dólar $1.510
A4: COSTO TOTAL DEL EVENTO | D4: YA PAGADO | F4: FALTA DESEMBOLSAR | H4: URGENTE · tramos 1 y 2
A5: 236647.21 | D5: 55891.15 | F5: 180756.06 | H5: 52564.09
A7: ✔ | B7: Rubro | C7: Proveedor | D7: Concepto | E7: A pagar | F7: Cuándo | G7: Cómo se paga | H7: Contacto | I7: Teléfono / mail | J7: Notas
A8: 1 · VENCIDO O YA FACTURADO | J8: =SUM(E9:E11)
A9: ☐ | B9: Sede | C9: La Rural | D9: Saldo del contrato CC-00957, cuota 1 de 2 | E9: 15777 | F9: 24 ago — VENCIDA | G9: Transferencia | H9: Victoria Grosi · vgrosi@larural.com.ar | I9: congresosyeventos@larural.com.ar | J9: Lleva 10 días vencida.
A10: ☐ | B10: Merch | C10: REMERASYESTAMPADOS | D10: Remeras premium x250 — factura 2601017 | E10: 2780.64 | F10: facturado 16 ago | G10: USDT BEP20 | H10: Leandro Petracci · CUIT 20-30367082-4 | I10: Uruguay 41, Villa Martelli | J10: Wallet 0xae874c3db52ca1e45604549a5527f450a877b97a
A11: ☐ | B11: Merch | C11: REMERASYESTAMPADOS | D11: Bordado de 940 gorras — factura 2601016 | E11: 1721.95 | F11: facturado 10 ago | G11: USDT BEP20 | H11: Leandro Petracci · CUIT 20-30367082-4 | I11: Uruguay 41, Villa Martelli | J11: Mismo wallet que las remeras.
A12: 2 · ANTICIPOS QUE DESTRABAN CONTRATOS | J12: =SUM(E13:E14)
A13: ☐ | B13: Técnica | C13: Grupo MET · Lalo Aizenberg | D13: Producción técnica — resto del anticipo del 50% | E13: 25000 | F13: urgente | G13: Transferencia / Mercury | H13: Lalo Aizenberg | I13: 11 6411-6748 | J13: El 50% son US$30.000; ya se pagaron US$5.000 con la factura INV-11 del 31/07.
A14: ☐ | B14: Catering | C14: Grupo Ambient · Ángeles | D14: Catering — anticipo del 50% | E14: 7284.5 | F14: urgente | G14: Transferencia | H14: Ángeles | I14: angeles@grupoambient.com.ar | J14: Total cerrado US$14.569 por las dos propuestas.
A15: 3 · PROVEEDORES DEL PREDIO — firmar y señar | J15: =SUM(E16:E24)
A16: ☐ | B16: Mobiliario | C16: FDL Eventos · Federico | D16: 5.500 sillas + flete | E16: 20674.17 | F16: a definir | G16: A resolver | H16: Federico | I16: 11 4403-0698 / 11 4040-7012 | J16: PENDIENTE: no confirmaron si pueden facturar al exterior. Lo hacen con un tercero que emite en EE.UU.
A17: ☐ | B17: Infraestructura | C17: La Rural | D17: Armado de stands | E17: 9270 | F17: a definir | G17: Transferencia | H17: Arq. Christian Riccio | I17: +54 9 11 3481-2179 | J17: criccio@larural.com.ar · falta pedirle los espejos.
A18: ☐ | B18: Servicios | C18: Road Seguridad S.A. | D18: 263 h de vigilancia + planos + supervisión | E18: 5784.7 | F18: a definir | G18: Transferencia | H18: Javier Celiz | I18: Cel 11 6303-7845 · Of. 4756-5691 | J18: presupuestos@roadseguridad.com.ar · versión V3 del 12/08, lista para firmar.
A19: ☐ | B19: Servicios | C19: Vittal | D19: Servicio médico, 3 días | E19: 4658.94 | F19: a definir | G19: A resolver | H19: vtomas@vittal.com.ar | I19: — | J19: PENDIENTE: tampoco confirmaron si pueden facturar al exterior.
A20: ☐ | B20: Servicios | C20: Higia Eventos | D20: Limpieza, 205,5 h — ANTICIPO 50% | E20: 1349.21 | F20: antes del armado | G20: Transferencia | H20: Malena Carrizo / Yanina Cruz | I20: malena.carrizo@higiaeventos.com | J20: Piden 50% de anticipo antes del armado. El saldo (US$1.349) va contra el evento.
A21: ☐ | B21: Servicios | C21: Gale Servicios | D21: Retiro de residuos — 100% ADELANTADO | E21: 1179.24 | F21: antes del evento | G21: Transferencia | H21: Yanina Cruz | I21: info@galeservicios.com | J21: Se factura 100% por adelantado. Trabajan con ARCILLEX; hay que estar dado de alta como generador.
A22: ☐ | B22: Servicios | C22: La Rural | D22: Conectividad WiFi, 2 redes privadas | E22: 1174.79 | F22: a definir | G22: Transferencia | H22: Gonzalo | I22: conectividad@larural.com.ar | J22: Presupuesto N.º 2 del 05/08. Ajusta por IPC.
A23: ☐ | B23: Servicios | C23: Chanes Seguros | D23: Seguro de accidentes, 150 personas | E23: 631.23 | F23: antes del armado | G23: Transferencia | H23: Néstor | I23: nestor@chanesseguros.com.ar | J23: Lo exige La Rural para habilitar. Premio único.
A24: ☐ | B24: Mobiliario | C24: A definir | D24: Montaje, acomodación y desmontaje de sillas | E24: 596.03 | F24: a definir | G24: Transferencia | H24: — | I24: — | J24: EN NEGOCIACIÓN: cerrar el número antes de firmar las sillas.
A25: 4 · PROGRAMADO | J25: =SUM(E26:E29)
A26: ☐ | B26: Merch | C26: REMERASYESTAMPADOS | D26: Pañuelos — saldo 50% (parte Argentina) | E26: 3429.73 | F26: 13 sep | G26: USDT BEP20 | H26: Leandro Petracci | I26: Uruguay 41, Villa Martelli | J26: Factura 2601019 por 5.276,51 USDT; a Argentina le toca el 65%.
A27: ☐ | B27: Sede | C27: La Rural | D27: Saldo del contrato CC-00957, cuota 2 de 2 | E27: 15777 | F27: 23 sep | G27: Transferencia | H27: Victoria Grosi | I27: vgrosi@larural.com.ar
A28: ☐ | B28: Merch | C28: DERQUI IMPRESIONES | D28: Gráfica Argentina — saldo | E28: 1192.37 | F28: 13 sep | G28: USDT BEP20 | H28: Germán Marino · CUIT 20-37540906-3 | I28: Charrúa 3366, CABA | J28: A CONFIRMAR: la factura 2601014 viene por el total, no por el saldo.
A29: ☐ | B29: Merch | C29: LEOTEX | D29: Lanyards — saldo | E29: 816.1 | F29: 13 sep | G29: USDT BEP20 | H29: DNI 33914106 | I29: Marengo 4178, Villa Ballester | J29: A CONFIRMAR: la factura 2601018 viene por el total, no por el saldo.
A30: 5 · RESTO DEL SALDO — sin fecha acordada | J30: =SUM(E31:E35)
A31: ☐ | B31: Técnica | C31: Grupo MET · Lalo Aizenberg | D31: Producción técnica — saldo del 50% | E31: 30000 | F31: a definir | G31: Transferencia / Mercury | H31: Lalo Aizenberg | I31: 11 6411-6748 | J31: Falta el PDF con el alcance final.
A32: ☐ | B32: Técnica | C32: Grupo MET · Lalo Aizenberg | D32: Entelado del pabellón | E32: 16225.17 | F32: a definir | G32: Transferencia | H32: Lalo Aizenberg | I32: 11 6411-6748
A33: ☐ | B33: Técnica | C33: Grupo MET · Lalo Aizenberg | D33: Circuito cerrado de cámaras (CCTV) | E33: 6209 | F33: a definir | G33: Transferencia | H33: Lalo Aizenberg | I33: 11 6411-6748 | J33: Con grúa incluida.
A34: ☐ | B34: Catering | C34: Grupo Ambient · Ángeles | D34: Catering — saldo del 50% | E34: 7284.5 | F34: a definir | G34: Transferencia | H34: Ángeles | I34: angeles@grupoambient.com.ar
A35: ☐ | B35: Servicios | C35: Higia Eventos | D35: Limpieza — saldo del 50% | E35: 1349.2 | F35: contra el evento | G35: Transferencia | H35: Malena Carrizo | I35: malena.carrizo@higiaeventos.com
A36: 6 · SIN COTIZAR — pedir presupuesto | J36: =SUM(E37:E40)
A37: ☐ | B37: Servicios | C37: A definir | D37: Ecobaños | F37: pedir | G37: — | H37: — | I37: — | J37: Decidido que van ecobaños. Sin cotizar: hoy entra en cero.
A38: ☐ | B38: Merch | C38: A definir | D38: Marquetería y enmarcado | F38: pedir | G38: — | H38: — | I38: — | J38: Certificaciones y premios. Sin cotizar.
A39: ☐ | B39: Merch | C39: A definir | D39: Cheques, escarapelas, diplomas, placas y manillas | F39: pedir | G39: — | H39: — | I39: — | J39: Lo único del merch que las facturas no cubren.
A40: ☐ | B40: Mobiliario | C40: A definir | D40: Replanteo de sillas con ingeniero | F40: pedir | G40: — | H40: — | I40: — | J40: Va aparte de la dirección técnica de La Rural.
A41: 7 · AJUSTE DE CONCILIACIÓN | J41: =SUM(E42:E42)
A42: ☐ | B42: Merch | C42: — | D42: Diferencia de tipo de cambio y saldo de gráfica a confirmar | E42: 590.59 | F42: — | G42: — | H42: — | I42: — | J42: Las facturas de merch se emitieron a dólar $1.535 y los pagos de junio se hicieron a $1.475, así que las mitades no suman exacto. El grueso es el saldo de la gráfica de Argentina: el master dice US$1.839 y la factura 2601014 viene por US$2.385.
...

Sheet CONTACTOS
A1: CONTACTOS DE PROVEEDORES
A3: Proveedor | B3: Persona | C3: Mail | D3: Teléfono / dato fiscal
A4: La Rural — contrato y eventos | B4: Victoria Grosi | C4: vgrosi@larural.com.ar | D4: congresosyeventos@larural.com.ar
A5: La Rural — infraestructura | B5: Arq. Christian Riccio | C5: criccio@larural.com.ar | D5: +54 9 11 3481-2179
A6: La Rural — conectividad | B6: Gonzalo | C6: conectividad@larural.com.ar | D6: —
A7: Grupo MET — técnica y entelado | B7: Lalo Aizenberg | C7: lalo@somosgrupomet.com | D7: 11 6411-6748
A8: Grupo Ambient — catering | B8: Ángeles | C8: angeles@grupoambient.com.ar | D8: —
A9: FDL Eventos — sillas | B9: Federico | C9: fdleventos@gmail.com | D9: 11 4403-0698 / 11 4040-7012
A10: Road Seguridad S.A. | B10: Javier Celiz | C10: presupuestos@roadseguridad.com.ar | D10: Cel 11 6303-7845 · Of. 4756-5691/1435
A11: Vittal — servicio médico | B11: — | C11: vtomas@vittal.com.ar | D11: —
A12: Higia Eventos — limpieza | B12: Malena Carrizo / Yanina Cruz | C12: malena.carrizo@higiaeventos.com | D12: yanina.cruz@higiaeventos.com
A13: Gale Servicios — residuos | B13: Yanina Cruz | C13: info@galeservicios.com | D13: —
A14: Chanes Seguros | B14: Néstor | C14: nestor@chanesseguros.com.ar | D14: —
... A18: TEXTIL RYU — gorras | B18: — | C18: CUIT 30-71927319-6 | D18: Larrea 377, Balvanera · YA PAGADO

Sheet RESUMEN
A1: RESUMEN POR TRAMO
A3: Tramo | B3: USD | D3: % del total
A4: 1 · VENCIDO O YA FACTURADO | B4: =CHECKLIST!J8 | C4: =REPT("|",ROUND(B4/$B$12*60,0)) | D4: =B4/$B$12
A5: 2 · ANTICIPOS QUE DESTRABAN CONTRATOS | B5: =CHECKLIST!J12 | C5: =REPT("|",ROUND(B5/$B$12*60,0)) | D5: =B5/$B$12
A6: 3 · PROVEEDORES DEL PREDIO — firmar y señar | B6: =CHECKLIST!J15 | C6: =REPT("|",ROUND(B6/$B$12*60,0)) | D6: =B6/$B$12
A7: 4 · PROGRAMADO | B7: =CHECKLIST!J25 | C7: =REPT("|",ROUND(B7/$B$12*60,0)) | D7: =B7/$B$12
A8: 5 · RESTO DEL SALDO — sin fecha acordada | B8: =CHECKLIST!J30 | C8: =REPT("|",ROUND(B8/$B$12*60,0)) | D8: =B8/$B$12
A9: 6 · SIN COTIZAR — pedir presupuesto | B9: =CHECKLIST!J36 | C9: =REPT("|",ROUND(B9/$B$12*60,0)) | D9: =B9/$B$12
A10: 7 · AJUSTE DE CONCILIACIÓN | B10: =CHECKLIST!J41 | C10: =REPT("|",ROUND(B10/$B$12*60,0)) | D10: =B10/$B$12
A12: TOTAL A DESEMBOLSAR | B12: =SUM(B4:B10)
