Workbook

Sheet LEEME
A1: CUMBRE 2026 · Consolidado de gastos y pagos
A2: Unifica "Cronograma_Pagos_Cumbre.xlsx" y "INVERSIÓN GIRA CUMBRE 2026.xlsx" en una sola fuente de verdad.
A4: Fecha de corte | B4: Todo el análisis está calculado al 02/09/2026 (celda B2 de la hoja TABLERO). Cambiala y se recalcula todo.
A5: Fuente 1 · CRONOGRAMA | B5: Cronograma_Pagos_Cumbre (1).xlsx — Google Drive id 1MbTsbcMKau4WA4V2-0PM7EtJv2w4XA5P. Aporta el calendario de cuotas y el histórico de pagos.
A6: Fuente 2 · MASTER | B6: INVERSIÓN GIRA CUMBRE 2026.xlsx — Google Drive id 1rRjt9YDSJKZR23nFlHJrAOf9CENc3CL2. Aporta contratos/reservas y el presupuesto línea por línea de cada evento.
A8: Cómo leer los colores | B8: Azul = dato cargado a mano (editable). Negro = fórmula. Verde = link a otra hoja de este libro. Relleno amarillo = requiere decisión tuya.
A9: Rojo / Ámbar / Verde | B9: Rojo = vencido o contradicción entre fuentes. Ámbar = vence dentro de 30 días o dato dudoso. Verde = conciliado.
A11: Supuesto de tipo de cambio | B11: Las hojas por evento del MASTER están en moneda local con tasas inconsistentes. Ver hoja EVENTOS, columna "Nota FX": ahí está la tasa que se usó para cada conversión y por qué.
A12: Supuesto de no duplicación | B12: CALENDARIO UNIFICADO (cuotas futuras y pagadas) y PAGOS REALIZADOS (histórico) son conjuntos disjuntos: el histórico termina el 03/07/2026 y el calendario empieza el 10/07/2026. Sumarlos NO duplica.
A13: Orden de las hojas de datos | B13: CALENDARIO UNIFICADO, PAGOS REALIZADOS y CONTRATOS están agrupados por país en orden de gira (Ecuador → España) y, dentro de cada país, por bloque: Lugar, Salas MM, Técnica, Producción, Dinámica, Merch, Catering, Trámites, Equipo. Cada país cierra con su subtotal.
A14: Cómo reordenar | B14: Las columnas País y Bloque están repetidas en cada fila de detalle y el filtro está activo en la fila de encabezado: podés filtrar por bloque para ver, por ejemplo, todos los pagos de Lugar de la gira. Las bandas azules son títulos, no datos: si ordenás la tabla se mezclan, mejor usá el filtro.
A16: Advertencia importante | B16: El presupuesto de la hoja EVENTOS ($1.087.979) y el calendario de pagos ($417.765) NO son comparables: el primero es el costo total de producción de cada evento, el segundo sólo los contratos con anticipo/saldo. No los sumes.
A18: Qué falta cargar | B18: Colombia 2da no tiene hoja de presupuesto en el MASTER. Perú, España y Colombia 2da no tienen ninguna cuota cargada en el calendario.
A19: Gastos de equipo en país | B19: La hoja GASTOS EQUIPO está vacía a propósito: es el destino de lo que cargue el agente de WhatsApp. Hoy esos gastos no viven en ninguno de los dos archivos originales.

Sheet TABLERO
A1: Tablero por país
A2: Presupuesto vs pagado vs pendiente. La columna "Brecha" mide cuánto se contradicen las dos fuentes. | E2: Fecha de corte → | G2: 46267
A4: País | B4: Presupuesto evento (MASTER, USD) | C4: Pagado según hoja del evento | D4: Pagado según CRONOGRAMA | E4: Brecha entre fuentes | F4: Programado (pendiente) | G4: VENCIDO al corte | H4: Fecha evento CRONOGRAMA | I4: Fecha evento MASTER | J4: Estado
A5: Ecuador | B5: 80279.73 | C5: 73773.65 | D5: 34991 | E5: =IFERROR(D5-C5,"") | H5: 25/07/2026 | I5: Quito, Ecuador Sabado 25/07/2026 Domingo 26/07/2026 | J5: fuentes no cierran
A6: Panamá | B6: 71839.07 | C6: 71372 | D6: 62012.6 | E6: =IFERROR(D6-C6,"") | H6: 08/08/2026 | I6: Panama City, Panama -Sabado 09/08/2026 Domingo 10/08/2026 | J6: fuentes no cierran
A7: Rep. Dominicana | B7: 68110.94 | C7: 68110.94 | D7: 50740 | E7: =IFERROR(D7-C7,"") | H7: 15/08/2026 | I7: Santo Domingo, Republica Dominicana -Sabado 15/08/2026 Domingo 16/08/2026 | J7: fuentes no cierran
A8: Colombia | B8: 129377.17 | D8: 86480 | E8: =IFERROR(D8-C8,"") | F8: 1522 | G8: 1522 | H8: 29/08/2026 | I8: Medellin, Colombia -Sabado 26/09/2026 Domingo 27/09/2026 | J8: VENCIDO · fuentes no cierran
A9: México | B9: 47415.59 | C9: 18916.82 | D9: 11145 | E9: =IFERROR(D9-C9,"") | F9: 26785 | G9: 26785 | H9: 05/09/2026 | I9: CDMX, Mexico -Sabado 1/11/2026 Domingo 2/11/2026 | J9: VENCIDO · fuentes no cierran
A10: Chile | B10: 148642.4 | C10: 3.48 | D10: 19693 | E10: =IFERROR(D10-C10,"") | F10: 45948 | G10: 22974 | H10: 12/09/2026 | I10: Chile -Sabado 12/09/2026 Domingo 13/09/2026 | J10: VENCIDO · fuentes no cierran
A11: Uruguay | B11: 88265.08 | D11: 1000 | E11: =IFERROR(D11-C11,"") | F11: 60612 | G11: 30306 | H11: 19/09/2026 | I11: Punta del Este, Uruguay -Sabado 19/09/2026 Domingo 20/09/2026 | J11: VENCIDO · fuentes no cierran
A12: Argentina | B12: 176159 | D12: 53494 | E12: =IFERROR(D12-C12,"") | F12: 40336 | G12: 16057 | H12: 03/10/2026 | I12: Buenos Aires, Argentina -Sabado 3/010/2026 Domingo 4/10/2026 | J12: VENCIDO · fuentes no cierran
A13: Salvador | B13: 61904.28 | D13: 7376 | E13: =IFERROR(D13-C13,"") | F13: 17213 | G13: 8606.5 | H13: 10/10/2026 | I13: San Salvador, Salvador -Sabado 07/11/2026 Domingo 08/11/2026 | J13: VENCIDO · fuentes no cierran
A14: Colombia 2da | E14: =IFERROR(D14-C14,"") | H14: 31/10/2026 | I14: sin hoja en el MASTER | J14: sin presupuesto cargado · sin pagos en el calendario
A15: Costa Rica | B15: 77920.25 | D15: 32494 | E15: =IFERROR(D15-C15,"") | F15: 32495 | H15: 07/11/2026 | I15: San José, Costa Rica -Sabado 01/08/2026 Domingo 02/08/2026 | J15: fuentes no cierran
A16: Perú | B16: 51504.27 | E16: =IFERROR(D16-C16,"") | H16: 14/11/2026 | I16: Lima, Perú -Sabado //2026 Domingo //2026 | J16: sin pagos en el calendario
A17: Guatemala | B17: 35333.97 | D17: 2000 | E17: =IFERROR(D17-C17,"") | F17: 4000 | H17: 21/11/2026 | I17: Ciudad de Guatemala, Guatemana-Sabado 14/11/2026 Domingo 15/11/2026 | J17: fuentes no cierran
A18: España | B18: 51227.61 | E18: =IFERROR(D18-C18,"") | H18: 28/11/2026 | I18: Madrid, España -Sabado 28/11/2026 Domingo 29/11/2026 | J18: sin pagos en el calendario
A19: TOTAL | B19: =SUM(B5:B18) | C19: =SUM(C5:C18) | D19: =SUM(D5:D18) | E19: =SUM(E5:E18) | F19: =SUM(F5:F18) | G19: =SUM(G5:G18)
A21: Lectura rápida
A22: Pendiente real del calendario | B22: =TABLERO!F19 | D22: Las hojas resumen del CRONOGRAMA informan $417.765,32 porque suman también las 29 cuotas ya pagadas.
A23: Vencido al corte | B23: =TABLERO!G19 | D23: 10 cuotas en estado "Programado" con fecha anterior a la fecha de corte.
A24: Brecha entre las dos fuentes | B24: =SUMPRODUCT(ABS(TABLERO!E5:E18)) | D24: Suma de diferencias absolutas: cuánto dinero está registrado como pagado en un archivo y no en el otro.

Sheet CALENDARIO UNIFICADO
A1: Calendario unificado de cuotas
A2: Las 54 cuotas del CRONOGRAMA agrupadas por país (orden de gira) y, dentro de cada país, por bloque.
A4: Bloque | B4: Fecha pago | C4: Concepto / proveedor | D4: Cuota | E4: Monto USD | F4: Estado | G4: Días vs corte | H4: Semáforo | I4: País | J4: Contradice al MASTER
A5: Ecuador · evento 25 jul
A6: LUGAR
A7: Lugar | B7: 46218 | C7: Wyndham Quintas (Salas MM) | D7: Pago total (100%) | E7: 1706 | F7: Pagado | G7: =IF(F7="Pagado","",TABLERO!$G$2-B7) | H7: =IF(F7="Pagado","PAGADO",IF(B7<TABLERO!$G$2,"VENCIDO",IF(B7<=TABLERO!$G$2+30,"< 30 dias","futuro"))) | I7: Ecuador
A8: TÉCNICA
A9: Técnica | B9: 46223 | C9: Jhon (técnica) - saldo | D9: Pago total | E9: 5500 | F9: Pagado | G9: =IF(F9="Pagado","",TABLERO!$G$2-B9) | H9: =IF(F9="Pagado","PAGADO",IF(B9<TABLERO!$G$2,"VENCIDO",IF(B9<=TABLERO!$G$2+30,"< 30 dias","futuro"))) | I9: Ecuador
A10: PRODUCCIÓN
A11: Producción | B11: 46218 | C11: Unifilas | D11: Pago total (100%) | E11: 600 | F11: Pagado | G11: =IF(F11="Pagado","",TABLERO!$G$2-B11) | H11: =IF(F11="Pagado","PAGADO",IF(B11<TABLERO!$G$2,"VENCIDO",IF(B11<=TABLERO!$G$2+30,"< 30 dias","futuro"))) | I11: Ecuador
A12: MERCH
A13: Merch | B13: 46218 | C13: Jorge (gorras, bolsas, pañuelos, camisetas) - saldo | D13: Pago total | E13: 2015 | F13: Pagado | G13: =IF(F13="Pagado","",TABLERO!$G$2-B13) | H13: =IF(F13="Pagado","PAGADO",IF(B13<TABLERO!$G$2,"VENCIDO",IF(B13<=TABLERO!$G$2+30,"< 30 dias","futuro"))) | I13: Ecuador
A14: Merch | B14: 46218 | C14: Jorge (pañuelos RD) - saldo | D14: Pago total | E14: 1075 | F14: Pagado | G14: =IF(F14="Pagado","",TABLERO!$G$2-B14) | H14: =IF(F14="Pagado","PAGADO",IF(B14<TABLERO!$G$2,"VENCIDO",IF(B14<=TABLERO!$G$2+30,"< 30 dias","futuro"))) | I14: Ecuador
A15: Merch | B15: 46218 | C15: Placas reconocimiento | D15: Pago total (100%) | E15: 390 | F15: Pagado | G15: =IF(F15="Pagado","",TABLERO!$G$2-B15) | H15: =IF(F15="Pagado","PAGADO",IF(B15<TABLERO!$G$2,"VENCIDO",IF(B15<=TABLERO!$G$2+30,"< 30 dias","futuro"))) | I15: Ecuador | J15: MASTER dice "Pendiente" (100% sin abonar)
A16: Subtotal Ecuador | E16: =SUMIF($F$6:$F$15,"<>",$E$6:$E$15) | F16: =SUMIF($F$6:$F$15,"Programado",$E$6:$E$15) | G16: pendiente →
A17: Panamá · evento 08 ago
A18: LUGAR
A19: Lugar | B19: 46219 | C19: Riu Plaza - saldo (70%) | D19: Cuota 1 de 2 (50%) | E19: 14688.66 | F19: Pagado | G19: =IF(F19="Pagado","",TABLERO!$G$2-B19) | H19: =IF(F19="Pagado","PAGADO",IF(B19<TABLERO!$G$2,"VENCIDO",IF(B19<=TABLERO!$G$2+30,"< 30 dias","futuro"))) | I19: Panamá
A20: Lugar | B20: 46219 | C20: Faranda (Salas MM) | D20: Cuota 1 de 2 (50%) | E20: 1000 | F20: Pagado | G20: =IF(F20="Pagado","",TABLERO!$G$2-B20) | H20: =IF(F20="Pagado","PAGADO",IF(B20<TABLERO!$G$2,"VENCIDO",IF(B20<=TABLERO!$G$2+30,"< 30 dias","futuro"))) | I20: Panamá | J20: La hoja Panamá registra $1.190 en Faranda + $1.375 en Hotel America Golden Tower
A21: Lugar | B21: 46232 | C21: Riu Plaza - saldo (70%) | D21: Cuota 2 de 2 (50%) | E21: 14688.66 | F21: Pagado | G21: =IF(F21="Pagado","",TABLERO!$G$2-B21) | H21: =IF(F21="Pagado","PAGADO",IF(B21<TABLERO!$G$2,"VENCIDO",IF(B21<=TABLERO!$G$2+30,"< 30 dias","futuro"))) | I21: Panamá
A22: Lugar | B22: 46232 | C22: Faranda (Salas MM) | D22: Cuota 2 de 2 (50%) | E22: 1000 | F22: Pagado | G22: =IF(F22="Pagado","",TABLERO!$G$2-B22) | H22: =IF(F22="Pagado","PAGADO",IF(B22<TABLERO!$G$2,"VENCIDO",IF(B22<=TABLERO!$G$2+30,"< 30 dias","futuro"))) | I22: Panamá | J22: La hoja Panamá registra $1.190 en Faranda + $1.375 en Hotel America Golden Tower
A23: TÉCNICA
A24: Técnica | B24: 46219 | C24: Plataforma AV | D24: Cuota 1 de 2 (50%) | E24: 7500 | F24: Pagado | G24: =IF(F24="Pagado","",TABLERO!$G$2-B24) | H24: =IF(F24="Pagado","PAGADO",IF(B24<TABLERO!$G$2,"VENCIDO",IF(B24<=TABLERO!$G$2+30,"< 30 dias","futuro"))) | I24: Panamá
A25: Técnica | B25: 46227 | C25: Plataforma AV | D25: Cuota 2 de 2 (50%) | E25: 7500 | F25: Pagado | G25: =IF(F25="Pagado","",TABLERO!$G$2-B25) | H25: =IF(F25="Pagado","PAGADO",IF(B25<TABLERO!$G$2,"VENCIDO",IF(B25<=TABLERO!$G$2+30,"< 30 dias","futuro"))) | I25: Panamá
A26: DINÁMICA
A27: Dinámica | B27: 46219 | C27: Varillas | D27: Cuota 1 de 2 (50%) | E27: 600 | F27: Pagado | G27: =IF(F27="Pagado","",TABLERO!$G$2-B27) | H27: =IF(F27="Pagado","PAGADO",IF(B27<TABLERO!$G$2,"VENCIDO",IF(B27<=TABLERO!$G$2+30,"< 30 dias","futuro"))) | I27: Panamá
A28: Dinámica | B28: 46232 | C28: Varillas | D28: Cuota 2 de 2 (50%) | E28: 600 | F28: Pagado | G28: =IF(F28="Pagado","",TABLERO!$G$2-B28) | H28: =IF(F28="Pagado","PAGADO",IF(B28<TABLERO!$G$2,"VENCIDO",IF(B28<=TABLERO!$G$2+30,"< 30 dias","futuro"))) | I28: Panamá
A29: MERCH
A30: Merch | B30: 46219 | C30: Impresos | D30: Cuota 1 de 2 (50%) | E30: 350 | F30: Pagado | G30: =IF(F30="Pagado","",TABLERO!$G$2-B30) | H30: =IF(F30="Pagado","PAGADO",IF(B30<TABLERO!$G$2,"VENCIDO",IF(B30<=TABLERO!$G$2+30,"< 30 dias","futuro"))) | I30: Panamá
A31: Merch | B31: 46222 | C31: Impresos | D31: Cuota 2 de 2 (50%) | E31: 350 | F31: Pagado | G31: =IF(F31="Pagado","",TABLERO!$G$2-B31) | H31: =IF(F31="Pagado","PAGADO",IF(B31<TABLERO!$G$2,"VENCIDO",IF(B31<=TABLERO!$G$2+30,"< 30 dias","futuro"))) | I31: Panamá
A32: Subtotal Panamá | E32: =SUMIF($F$18:$F$31,"<>",$E$18:$E$31) | F32: =SUMIF($F$18:$F$31,"Programado",$E$18:$E$31) | G32: pendiente →
A33: Rep. Dominicana · evento 15 ago
A34: LUGAR
A35: Lugar | B35: 46219 | C35: Crowne Plaza | D35: Cuota 1 de 2 (50%) | E35: 17000 | F35: Pagado | G35: =IF(F35="Pagado","",TABLERO!$G$2-B35) | H35: =IF(F35="Pagado","PAGADO",IF(B35<TABLERO!$G$2,"VENCIDO",IF(B35<=TABLERO!$G$2+30,"< 30 dias","futuro"))) | I35: Rep. Dominicana
A36: Lugar | B36: 46239 | C36: Crowne Plaza | D36: Cuota 2 de 2 (50%) | E36: 17000 | F36: Pagado | G36: =IF(F36="Pagado","",TABLERO!$G$2-B36) | H36: =IF(F36="Pagado","PAGADO",IF(B36<TABLERO!$G$2,"VENCIDO",IF(B36<=TABLERO!$G$2+30,"< 30 dias","futuro"))) | I36: Rep. Dominicana
A37: TÉCNICA
A38: Técnica | B38: 46219 | C38: Plataforma AV | D38: Cuota 1 de 2 (50%) | E38: 7500 | F38: Pagado | G38: =IF(F38="Pagado","",TABLERO!$G$2-B38) | H38: =IF(F38="Pagado","PAGADO",IF(B38<TABLERO!$G$2,"VENCIDO",IF(B38<=TABLERO!$G$2+30,"< 30 dias","futuro"))) | I38: Rep. Dominicana
A39: Técnica | B39: 46234 | C39: Plataforma AV | D39: Cuota 2 de 2 (50%) | E39: 7500 | F39: Pagado | G39: =IF(F39="Pagado","",TABLERO!$G$2-B39) | H39: =IF(F39="Pagado","PAGADO",IF(B39<TABLERO!$G$2,"VENCIDO",IF(B39<=TABLERO!$G$2+30,"< 30 dias","futuro"))) | I39: Rep. Dominicana
A40: DINÁMICA
A41: Dinámica | B41: 46219 | C41: Varillas | D41: Cuota 1 de 2 (50%) | E41: 600 | F41: Pagado | G41: =IF(F41="Pagado","",TABLERO!$G$2-B41) | H41: =IF(F41="Pagado","PAGADO",IF(B41<TABLERO!$G$2,"VENCIDO",IF(B41<=TABLERO!$G$2+30,"< 30 dias","futuro"))) | I41: Rep. Dominicana
...

Sheet PAGOS REALIZADOS
A1: Histórico de pagos ejecutados (marzo–julio 2026)
A2: Anticipos previos al arranque del calendario, agrupados por país y bloque. Conjunto disjunto del CALENDARIO UNIFICADO.
A4: Bloque | B4: Fecha | C4: Proveedor / concepto | D4: % del total | E4: Monto USD | F4: País | G4: País en el archivo original
A5: Ecuador · evento 25 jul
A6: LUGAR
A7: Lugar | B7: 46106 | C7: Quorum Quito - primer pago | D7: 30% | E7: 6911 | F7: Ecuador
A8: Lugar | B8: 46205 | C8: Ambulancia - pago completo | D8: 100% | E8: 500 | F8: Ecuador
A9: TÉCNICA
A10: Técnica | B10: 46171 | C10: Técnica (Jhon) - primer pago | D10: 50% | E10: 5500 | F10: Ecuador
A11: DINÁMICA
A12: Dinámica | B12: 46204 | C12: Varillas/camerino - Cesar - pago completo | D12: 100% | E12: 4936 | F12: Ecuador
A13: MERCH
A14: Merch | B14: 46181 | C14: Mambo (impresos) - primer pago | D14: 60% | E14: 1348 | F14: Ecuador
A15: Merch | B15: 46189 | C15: Jorge (gorras, bolsas, pañuelos, camisetas) - primer pago | D15: 50% | E15: 2000 | F15: Ecuador
A16: Merch | B16: 46197 | C16: Jorge (pañuelos RD) - primer pago | D16: ? | E16: 1600 | F16: Ecuador
A17: Merch | B17: 46204 | C17: Mambo (impresos) - saldo | D17: 40% | E17: 910 | F17: Ecuador
C18: Subtotal Ecuador | E18: =SUM(E6:E17)
A19: Panamá · evento 08 ago
A20: LUGAR
A21: Lugar | B21: 46114 | C21: Riu Plaza - primer pago | D21: 30% | E21: 12590.28 | F21: Panamá
A22: MERCH
A23: Merch | B23: 46198 | C23: Camisetas y bolsas - pago completo | D23: 100% | E23: 1145 | F23: Panamá
C24: Subtotal Panamá | E24: =SUM(E20:E23)
A25: Rep. Dominicana · evento 15 ago
A26: MERCH
A27: Merch | B27: 46199 | C27: Impresos - pago completo | D27: 100% | E27: 430 | F27: Rep. Dominicana
A28: Merch | B28: 46199 | C28: Bolsas - pago completo | D28: 100% | E28: 110 | F28: Rep. Dominicana
C29: Subtotal Rep. Dominicana | E29: =SUM(E26:E28)
A30: Colombia 1ra · evento 29 ago
A31: MERCH
A32: Merch | B32: 46181 | C32: Maleta pendones - primer pago | D32: 50% | E32: 120 | F32: Colombia 1ra | G32: Colombia
A33: Merch | B33: 46181 | C33: D'vinni sas - pago completo | D33: 100% | E33: 580 | F33: Colombia 1ra | G33: Pendones
A34: Merch | B34: 46192 | C34: Gorras - primer pago | D34: 50% | E34: 2000 | F34: Colombia 1ra | G34: Colombia
A35: Merch | B35: 46196 | C35: Maleta pendones - saldo | D35: 50% | E35: 120 | F35: Colombia 1ra | G35: Colombia
A36: Merch | B36: 46198 | C36: D'vinni sas - primer pago | D36: 50% | E36: 1094 | F36: Colombia 1ra | G36: Colombia
A37: Merch | B37: 46206 | C37: Pañuelos Colombia - primer pago | D37: 50% | E37: 3475 | F37: Colombia 1ra | G37: Colombia
C38: Subtotal Colombia 1ra | E38: =SUM(E31:E37)
A39: México · evento 05 sep
A40: LUGAR
A41: Lugar | B41: 46114 | C41: World Trade Center Mexiquense - primer pago | D41: 50% | E41: 11145 | F41: México
...

Sheet CONTRATOS
A1: Contratos y reservas (hoja PAGOS del MASTER)
A2: 44 contratos por país y bloque. "Saldo master" es el saldo escrito el día de la reserva: no se actualiza solo.
A4: Bloque | B4: Fecha reserva | C4: Proveedor | D4: Valor total | E4: % 1er pago | F4: 1er pago | G4: Saldo master | H4: Fecha saldo | I4: País | J4: Fila origen | K4: Alerta
A5: Ecuador · evento 25 jul
A6: LUGAR
A7: Lugar | B7: 46205 | C7: Ambulancia | D7: 500 | E7: 1 | I7: Ecuador | J7: 32 | K7: Contrato sin ningún dato de pago en el MASTER
A8: Lugar | B8: 46106 | C8: Quorum Quito | D8: 25456 | E8: 0.3 | F8: 6911 | G8: 18545 | I8: Ecuador | J8: 7
A9: SALAS MM
A10: Salas MM | C10: Wyndham Quintas | D10: 1706 | I10: Ecuador | J10: 45 | K10: Contrato sin ningún dato de pago en el MASTER
A11: TÉCNICA
A12: Técnica | B12: 46171 | C12: Tecnica (Jhon) | D12: 11000 | E12: 0.5 | F12: 5500 | G12: 5500 | H12: 46223 | I12: Ecuador | J12: 14
A13: PRODUCCIÓN
A14: Producción | C14: Unifilas | D14: 600 | I14: Ecuador | J14: 42 | K14: Contrato sin ningún dato de pago en el MASTER
A15: DINÁMICA
A16: Dinámica | B16: 46204 | C16: Varillas/camerino - Cesar | D16: 4936 | E16: 1 | I16: Ecuador | J16: 31 | K16: Contrato sin ningún dato de pago en el MASTER
A17: MERCH
A18: Merch | B18: 46189 | C18: Jorge (Gorras, bolsas, pañuelos, camisetas) | D18: 4015 | E18: 0.5 | F18: 2000 | G18: 2015 | H18: 46218 | I18: Ecuador | J18: 18
A19: Merch | B19: 46197 | C19: Jorge (pañuelos RD) | D19: 2675 | E19: ? | F19: 1600 | G19: 1075 | H19: 46218 | I19: Ecuador | J19: 20 | K19: % del primer pago desconocido
A20: Merch | B20: 46181 | C20: Mambo (impresos) | D20: 2246 | E20: 0.6 | F20: 1347.6 | G20: 898.4 | H20: 46204 | I20: Ecuador | J20: 15
A21: Merch | C21: Placas reconocimiento | D21: 390 | E21: 1 | F21: Pendiente | I21: Ecuador | J21: 35 | K21: Sin abonar según MASTER — revisar contra el CALENDARIO
A22: CATERING
A23: Catering | B23: 46205 | C23: Quorum Quito | D23: 5074 | E23: 1 | F23: Pendiente | I23: Ecuador | J23: 33 | K23: Sin abonar según MASTER — revisar contra el CALENDARIO
C24: Subtotal Ecuador | D24: =SUM(D6:D23) | G24: =SUM(G6:G23)
A25: Panamá · evento 08 ago
A26: LUGAR
A27: Lugar | B27: 46114 | C27: Riu plaza | D27: 41967.6 | E27: 0.3 | F27: 12590.28 | G27: 29377.32 | I27: Panamá | J27: 6
A28: SALAS MM
A29: Salas MM | C29: Faranda | D29: 2000 | I29: Panamá | J29: 44 | K29: Contrato sin ningún dato de pago en el MASTER
A30: TÉCNICA
A31: Técnica | C31: Plataforma AV | D31: 15000 | I31: Panamá | J31: 46 | K31: Contrato sin ningún dato de pago en el MASTER
A32: DINÁMICA
A33: Dinámica | C33: VArillas | D33: 1200 | E33: aprox | I33: Panamá | J33: 49 | K33: Contrato sin ningún dato de pago en el MASTER
A34: MERCH
A35: Merch | B35: 46198 | C35: Camisetas y bolsas | D35: 1145 | E35: 1 | F35: 1145 | I35: Panamá | J35: 28
A36: Merch | C36: Impresos | D36: 700 | I36: Panamá | J36: 48 | K36: Contrato sin ningún dato de pago en el MASTER
C37: Subtotal Panamá | D37: =SUM(D26:D36) | G37: =SUM(G26:G36)
A38: Rep. Dominicana · evento 15 ago
A39: LUGAR
A40: Lugar | C40: Crowne plaza | D40: 34000 | I40: Rep. Dominicana | J40: 43 | K40: Contrato sin ningún dato de pago en el MASTER
A41: TÉCNICA
...

Sheet EVENTOS
A1: Presupuesto por evento y tipos de cambio
A2: Cada hoja del MASTER está en su moneda. Acá se documenta la tasa usada y por qué.
A4: País | B4: Hoja origen | C4: Moneda | D4: Total en moneda local | E4: Tasa a USD | F4: Total USD | G4: Pagado local | H4: Pagado USD | I4: Nota FX | J4: Fecha en el MASTER
A5: Ecuador | B5: Ecuador (25 Jul-26 Jul) | C5: USD | D5: 80279.725 | E5: 1 | F5: =D5*E5 | G5: 73773.65 | H5: =IF(G5="","",G5*E5) | I5: USD directo | J5: Quito, Ecuador Sabado 25/07/2026 Domingo 26/07/2026
A6: Panamá | B6: Panama (09 ago-10 ago) | C6: USD | D6: 71839.065 | E6: 1 | F6: =D6*E6 | G6: 71372 | H6: =IF(G6="","",G6*E6) | I6: USD directo | J6: Panama City, Panama -Sabado 09/08/2026 Domingo 10/08/2026
A7: Rep. Dominicana | B7: Rep D. (15 ago-16 ago) | C7: USD | D7: 68110.941 | E7: 1 | F7: =D7*E7 | G7: 68110.941 | H7: =IF(G7="","",G7*E7) | I7: Hoja ya en USD (tasa 1.0) | J7: Santo Domingo, Republica Dominicana -Sabado 15/08/2026 Domingo 16/08/2026
A8: Colombia | B8: Colombia (29 ago - 30 ago) | C8: COP | D8: 478695540 | E8: 0.00027027027 | F8: =D8*E8 | G8: 0 | H8: =IF(G8="","",G8*E8) | I8: Presupuesto /3700; la columna PAGADO usa /4080 | J8: Medellin, Colombia -Sabado 26/09/2026 Domingo 27/09/2026
A9: México | B9: Mexico (5 sep - 6 sep) | C9: MXN | D9: 803654 | E9: 0.059 | F9: =D9*E9 | G9: 320624 | H9: =IF(G9="","",G9*E9) | I9: Presupuesto x0.059; la columna PAGADO usa x0.051 | J9: CDMX, Mexico -Sabado 1/11/2026 Domingo 2/11/2026
A10: Chile | B10: Chile (12 sep-13 sep) | C10: USD | D10: 148642.4 | E10: 1 | F10: =D10*E10 | G10: 3.485 | H10: =IF(G10="","",G10*E10) | I10: Celda de tasa vacia/0 -> se toma como USD | J10: Chile -Sabado 12/09/2026 Domingo 13/09/2026
A11: Uruguay | B11: Uruguay (19 sep-20 sep) | C11: USD | D11: 88265.08 | E11: 1 | F11: =D11*E11 | G11: 0 | H11: =IF(G11="","",G11*E11) | I11: Celda de tasa 0 -> se toma como USD | J11: Punta del Este, Uruguay -Sabado 19/09/2026 Domingo 20/09/2026
A12: Costa Rica | B12: Costa Rica (1 ago-2 ago) | C12: USD | D12: 77920.246 | E12: 1 | F12: =D12*E12 | G12: 0 | H12: =IF(G12="","",G12*E12) | I12: Sin celda de tasa | J12: San José, Costa Rica -Sabado 01/08/2026 Domingo 02/08/2026
A13: Argentina | B13: Argentina (3 oct-4 oct) | C13: USD | D13: 176159 | E13: 1 | F13: =D13*E13 | G13: 0 | H13: =IF(G13="","",G13*E13) | I13: Tasa 1.0 | J13: Buenos Aires, Argentina -Sabado 3/010/2026 Domingo 4/10/2026
A14: Salvador | B14: Salvador (7 nov-8 nov) | C14: USD | D14: 61904.281 | E14: 1 | F14: =D14*E14 | G14: 0 | H14: =IF(G14="","",G14*E14) | I14: Tasa heredada de Mexico (link roto) | J14: San Salvador, Salvador -Sabado 07/11/2026 Domingo 08/11/2026
A15: Guatemala | B15: Guatemala (14 nov-15 nov) | C15: USD | D15: 35333.97 | E15: 1 | F15: =D15*E15 | G15: 0 | H15: =IF(G15="","",G15*E15) | I15: Tasa heredada de Mexico (link roto) | J15: Ciudad de Guatemala, Guatemana-Sabado 14/11/2026 Domingo 15/11/2026
A16: Perú | B16: Perú | C16: USD | D16: 51504.27 | E16: 1 | F16: =D16*E16 | G16: 0 | H16: =IF(G16="","",G16*E16) | I16: Tasa heredada de Mexico (link roto) | J16: Lima, Perú -Sabado //2026 Domingo //2026
A17: España | B17: España (28 nov-29 nov) | C17: EUR | D17: 44545.75 | E17: 1.15 | F17: =D17*E17 | G17: 0 | H17: =IF(G17="","",G17*E17) | I17: EUR x1.15 | J17: Madrid, España -Sabado 28/11/2026 Domingo 29/11/2026
A18: TOTAL | F18: =SUM(F5:F17) | H18: =SUM(H5:H17)
A20: Colombia 2da (31/10/2026) no tiene hoja de presupuesto en el MASTER: su costo no está dentro de este total.

Sheet HALLAZGOS
A1: Hallazgos de la conciliación
A2: Ordenados por impacto. La columna "Acción" es lo que hay que decidir.
A4: # | B4: Severidad | C4: Hallazgo | D4: Evidencia | E4: Impacto USD | F4: Acción
A5: 1 | B5: ALTA | C5: El informe quincenal sobrestima el pendiente | D5: Las hojas PRESUPUESTO QUINCENAL y VISTA POR EVENTO suman las 54 filas del calendario, incluidas las 29 ya marcadas "Pagado". Informan $417.765,32 de pendiente. | E5: 188854.32 | F5: Reemplazar el informe a finanzas por la hoja TABLERO. Pendiente real: $228.911,00.
A6: 2 | B6: ALTA | C6: Cuotas vencidas sin pagar | D6: 10 cuotas en estado "Programado" con fecha anterior al 02/09/2026. La más vieja lleva 54 días (Colombia merch, 10/07). | E6: 106250.5 | F6: Confirmar con Erick cuáles se pagaron y no se marcaron, y cuáles están realmente en mora.
A7: 3 | B7: ALTA | C7: Las dos fuentes no cierran en pagos | D7: Suma de diferencias absolutas por país entre "pagado según la hoja del evento" y "pagado según el cronograma". | E7: 275818.32 | F7: Definir cuál archivo es la fuente de verdad de PAGOS. Propuesta: el consolidado, alimentado por el agente.
A8: 4 | B8: ALTA | C8: Colombia: $86.480 pagados que la hoja del evento reporta como $0 | D8: City Hall 2 x $36.500 + merch figuran "Pagado" en el cronograma. Las 64 líneas de la hoja Colombia tienen la columna Pago en 0. | E8: 86480 | F8: Cargar los pagos en la hoja de Colombia o migrar a este consolidado.
A9: 5 | B9: ALTA | C9: Fechas de evento en conflicto entre archivos | D9: Colombia: 29/08 vs 26-27/09 · México: 05/09 vs 01-02/11 · Costa Rica: 07/11 vs 01-02/08 · Salvador: 10/10 vs 07-08/11 · Guatemala: 21/11 vs 14-15/11 · Panamá: 08/08 vs 09-10/08. | F9: Fijar el calendario real de la gira. Toda la regla de pagos ("Lugar: 10 días antes") depende de esta fecha.
A10: 6 | B10: ALTA | C10: 14 contratos sin ningún dato de pago en el MASTER | D10: City Hall $73.000, Crowne Plaza $34.000, Plataforma AV Panamá y RD $15.000 c/u, Faranda $2.000, Wyndham Quintas $1.706, Varillas, Impresos, Unifilas, Ambulancia, Bolsas. | E10: 150382 | F10: La única traza de esos pagos es el cronograma. Adjuntar comprobantes antes del cierre contable.
A11: 7 | B11: MEDIA | C11: Salvador tiene dos sedes vivas | D11: Contrato pagado y programado: Círculo Militar ($24.589, $7.376 abonado). La hoja del evento presupuesta Hotel Hilton ($31.000 sala + $7.890 técnica). | E11: 31000 | F11: Confirmar sede con Aleja. Si se cambió, reclamar o reasignar el anticipo del Círculo Militar.
A12: 8 | B12: MEDIA | C12: Panamá: sala Mastermind pagada en dos hoteles | D12: El cronograma pagó Faranda "Salas MM" $2.000 en dos cuotas. La hoja Panamá registra $1.190 en Faranda y $1.375 en Hotel America Golden Tower, ambos pagados. | E12: 810 | F12: Reclamar el crédito no usado en Faranda (~$810).
A13: 9 | B13: MEDIA | C13: Contradicciones de estado en 5 conceptos | D13: Placas reconocimiento EC $390, Camisetas CO $433, Tarjetas platino CO $611, Intercoms AR $560: el cronograma los da por pagados o parcialmente pagados, el MASTER dice "Pendiente". | E13: 1994 | F13: Verificar contra extractos bancarios y unificar el estado en este consolidado.
A14: 10 | B14: MEDIA | C14: Ecuador cerró con saldo sin liquidar | D14: Evento del 25-26/07. Quinta by Wyndham: hospedaje $3.110 y salas MM/empresarios $2.082 sin pagar. Vuelos LATAM cruzados: $1.564 imputados a un sobrepeso de $260 y sólo $299 de $2.917 de vuelos. | E14: 6506.07 | F14: Liquidar con el hotel y corregir la imputación de LATAM.
A15: 11 | B15: MEDIA | C15: Ecuador: catering $5.074 nunca programado | D15: El MASTER lo marca "Pendiente"; el cronograma no tiene ninguna fila para el catering de Quorum Quito. El evento ya ocurrió. | E15: 5074 | F15: Confirmar si se pagó. Si no, es una deuda vencida hace 5 semanas.
A16: 12 | B16: MEDIA | C16: Guatemala: presupuesto 3x el contrato | D16: Contrato Parque de la Industria $5.000 ($1.500 abonado, saldo $3.500 en 2 cuotas). La hoja del evento presupuesta $14.351 de ítems del mismo venue. | E16: 9351 | F16: Pedir cotización firme a Michelle Taylor antes de fijar las cuotas de octubre y noviembre.
A17: 13 | B17: MEDIA | C17: Tres eventos sin ninguna cuota cargada | D17: Colombia 2da (31/10), Perú (14/11) y España (28/11) figuran con "-" en el cronograma. Perú y España tienen $51.504 y $51.228 de presupuesto; Colombia 2da no tiene ni hoja. | E17: 102732 | F17: Cargar contratos y fechas de pago. Son los tres últimos eventos del año y hoy no tienen plan financiero.
A18: 14 | B18: MEDIA | C18: Tipos de cambio incoherentes dentro de la misma hoja | D18: México usa 0,059 para presupuestar y 0,051 para pagos. Colombia usa 3.700 y 4.080. Chile y Uruguay tienen la celda de tasa en 0. Salvador, Guatemala y Perú apuntan al link de "peso mexicano a dólar" heredado por copiar la hoja. | F18: Fijar una tasa por evento en la hoja EVENTOS y usarla en todas las columnas.
A19: 15 | B19: BAJA | C19: El "Gral Resume" del MASTER está roto | D19: La columna PAGADO da #REF! en Guatemala y Perú, $0 en Panamá, Colombia, Argentina, Uruguay y España, y $3,48 en Chile. | F19: Dejar de usarlo. La hoja TABLERO lo reemplaza.
A20: 16 | B20: BAJA | C20: Etiquetas de cuota inconsistentes | D20: Colombia Gorras: una fila dice "Cuota 1 de 1 (100%)" por $1.000 y otra "Cuota 2 de 2 (50%)" por $1.000, cuando son las dos mitades del mismo saldo de $2.000. | F20: Normalizar el texto de cuota. El agente lo va a generar automáticamente.

Sheet GASTOS EQUIPO
A1: Gastos del equipo en país
A2: Hoja destino del agente de WhatsApp. Hoy estos gastos no existen en ninguno de los dos archivos originales.
A3: Fila 5 = ejemplo con formato esperado (tomado de la factura 2601020 de Panamá). Borrala cuando el agente empiece a escribir.
A4: ID | B4: Fecha | C4: País / evento | D4: Persona | E4: Rol | F4: Comercio / proveedor | G4: Concepto | H4: Categoría | I4: Moneda | J4: Monto local | K4: Tasa | L4: Monto USD | M4: Comprobante | N4: Estado | O4: N° factura reintegro
A5: GE-2026-0001 | B5: 46243 | C5: Panamá | D5: Carlos Andrés Calderón Arbeláez | E5: Staff | F5: Riba Smith | G5: Camerinos speakers / staff | H5: Camerinos | I5: USD | J5: 133.81 | K5: 1 | L5: =J5*K5 | M5: foto ticket WhatsApp | N5: Facturado | O5: 2601020
L6: =IF(J6="","",J6*K6)
L7: =IF(J7="","",J7*K7)
L8: =IF(J8="","",J8*K8)
L9: =IF(J9="","",J9*K9)
L10: =IF(J10="","",J10*K10)
L11: =IF(J11="","",J11*K11)
L12: =IF(J12="","",J12*K12)
L13: =IF(J13="","",J13*K13)
L14: =IF(J14="","",J14*K14)
L15: =IF(J15="","",J15*K15)
L16: =IF(J16="","",J16*K16)
L17: =IF(J17="","",J17*K17)
... L59: =IF(J59="","",J59*K59)
